Workbook

Sheet Synthèse
F2: Accord-Cadre IV (2014 -2019)
F3: de Recherche et de Vulgarisation forestières
B5: Nouvelles normes sylvicoles pour les peuplements purs équiennes d'épicéa
B7: 1. Evolution de la hauteur dominante selon les 5 classes de productivité
B9: Age | C9: Classe de productivité
C10: IV | D10: III | E10: II | F10: I | G10: 0
B11: 20 | C11: 8.8 | D11: 10.3 | E11: 11.8 | F11: 13.3 | G11: 14.7
B12: 25 | C12: 11.3 | D12: 13.1 | E12: 14.9 | F12: 16.8 | G12: 18.6
B13: 30 | C13: 13.6 | D13: 15.7 | E13: 17.9 | F13: 20 | G13: 22.2
B14: 35 | C14: 15.7 | D14: 18.1 | E14: 20.5 | F14: 23 | G14: 25.4
B15: 40 | C15: 17.6 | D15: 20.3 | E15: 22.9 | F15: 25.6 | G15: 28.3
B16: 45 | C16: 19.4 | D16: 22.2 | E16: 25.1 | F16: 27.9 | G16: 30.8
B17: 50 | C17: 21 | D17: 24 | E17: 27 | F17: 30 | G17: 33
B18: 55 | C18: 22.5 | D18: 25.6 | E18: 28.7 | F18: 31.8 | G18: 35
B19: 60 | C19: 23.8 | D19: 27 | E19: 30.2 | F19: 33.5 | G19: 36.7
B20: 65 | C20: 25 | D20: 28.3 | E20: 31.6 | F20: 34.9 | G20: 38.3
B21: 70 | C21: 26.1 | D21: 29.5 | E21: 32.9 | F21: 36.3 | G21: 39.6
B22: 75 | C22: 27.1 | D22: 30.6 | E22: 34 | F22: 37.5 | G22: -
B23: 80 | C23: 28.1 | D23: 31.6 | E23: 35.1 | F23: 38.6 | G23: -
B24: 85 | C24: 29 | D24: 32.5 | E24: 36.1 | F24: 39.6 | G24: -
B25: 90 | C25: 29.9 | D25: 33.4 | E25: 37 | F25: - | G25: -
B26: 95 | C26: 30.7 | D26: 34.3 | E26: 37.9 | F26: - | G26: -
B27: 100 | C27: 31.5 | D27: 35.1 | E27: 38.7 | F27: - | G27: -
B29: 2. Synthèse des nouvelles normes
C31: 2.1. Ecartement à la plantation : 2.5 x 2 m
B33: Productivité | D33: 1ère éclaircie | F33: Caractéristique de la coupe rase | K33: Accroissements et stabilité | O33: Recettes
B34: Classe | C34: H50 | D34: Age | E34: Ecl | F34: Age cible | G34: Hdom | H34: Cg | I34: Nha | J34: Vha | K34: AMC | L34: PTV | M34: AMV | N34: h/d | O34: VA Ecl | P34: VA Mab | Q34: VA Total
B35: années | C35: m | D35: années | E35: % | F35: années | G35: m | H35: cm | I35: N/ha | J35: m³/ha | K35: cm/an | L35: m³/ha | M35: m³/ha/an | O35: € /ha | P35: € /ha | Q35: € /ha
B36: 0 | C36: 33 | D36: =Ep0A!A$9 -> 17 | E36: =Ep0A!V$9 -> 32.643048 | F36: =Ep0A!A15 -> 53 | G36: =Ep0A!B15 -> 33.818501 | H36: =Ep0A!D15 -> 141.94769 | I36: =Ep0A!C15 -> 270.99 | J36: =Ep0A!F15 -> 610.19201 | K36: =H36/F36 -> 2.6782584 | L36: =Ep0A!T15 -> 1044.401 | M36: =Ep0A!S15 -> 19.70568 | N36: =Ep0A!U14 -> 76.43174 | O36: =Q36-P36 -> 9792.7631 | P36: =Ep0A!L$32 -> 16105.616 | Q36: =Ep0A!W$32 -> 25898.38
B37: 1 | C37: 30 | D37: =Ep1A!A$9 -> 19 | E37: =Ep1A!V$9 -> 32.646092 | F37: =Ep1A!A15 -> 55 | G37: =Ep1A!B15 -> 31.457775 | H37: =Ep1A!D15 -> 133.61478 | I37: =Ep1A!C15 -> 297.9 | J37: =Ep1A!F15 -> 562.28231 | K37: =H37/F37 -> 2.4293596 | L37: =Ep1A!T15 -> 949.74698 | M37: =Ep1A!S15 -> 17.268127 | N37: =Ep1A!U14 -> 75.551404 | O37: =Q37-P37 -> 8024.784 | P37: =Ep1A!L$32 -> 13960.126 | Q37: =Ep1A!W$32 -> 21984.91
B38: 2 | C38: 27 | D38: =Ep2A!A$9 -> 22 | E38: =Ep2A!V$9 -> 32.643291 | F38: =Ep2A!A16 -> 64 | G38: =Ep2A!B16 -> 30.92649 | H38: =Ep2A!D16 -> 138.0142 | I38: =Ep2A!C16 -> 276.48 | J38: =Ep2A!F16 -> 549.99471 | K38: =H38/F38 -> 2.1564718 | L38: =Ep2A!T16 -> 963.69281 | M38: =Ep2A!S16 -> 15.0577 | N38: =Ep2A!U15 -> 72.086748 | O38: =Q38-P38 -> 7837.4512 | P38: =Ep2A!L$33 -> 11571.962 | Q38: =Ep2A!W$33 -> 19409.413
B39: 3 | C39: 24 | D39: =Ep3A!A$9 -> 25 | E39: =Ep3A!V$9 -> 32.643992 | F39: =Ep3A!A17 -> 73 | G39: =Ep3A!B17 -> 29.672443 | H39: =Ep3A!D17 -> 138.00127 | I39: =Ep3A!C17 -> 272.61 | J39: =Ep3A!F17 -> 525.76649 | K39: =H39/F39 -> 1.8904283 | L39: =Ep3A!T17 -> 936.98551 | M39: =Ep3A!S17 -> 12.835418 | N39: =Ep3A!U16 -> 69.179587 | O39: =Q39-P39 -> 6913.8453 | P39: =Ep3A!L$34 -> 9254.8507 | Q39: =Ep3A!W$34 -> 16168.696
B40: 4 | C40: 21 | D40: =Ep4A!A$9 -> 29 | E40: =Ep4A!V$9 -> 32.646338 | F40: =Ep4A!A18 -> 83 | G40: =Ep4A!B18 -> 28.214954 | H40: =Ep4A!D18 -> 136.29899 | I40: =Ep4A!C18 -> 274.95 | J40: =Ep4A!F18 -> 498.45878 | K40: =H40/F40 -> 1.6421565 | L40: =Ep4A!T18 -> 895.24423 | M40: =Ep4A!S18 -> 10.786075 | N40: =Ep4A!U17 -> 66.486098 | O40: =Q40-P40 -> 5745.7636 | P40: =Ep4A!L$35 -> 7166.3941 | Q40: =Ep4A!W$35 -> 12912.158
C42: 2.2. Ecartement à la plantation : 2 x 2 m
B44: Productivité | D44: 1ère éclaircie | F44: Caractéristique de la coupe rase | K44: Accroissements et stabilité | O44: Recettes
B45: Classe | C45: H50 | D45: Age | E45: Ecl | F45: Age cible | G45: Hdom | H45: Cg | I45: Nha | J45: Vha | K45: AMC | L45: PTV | M45: AMV | N45: h/d | O45: VA Ecl | P45: VA Mab | Q45: VA Total
B46: années | C46: m | D46: années | E46: % | F46: années | G46: m | H46: cm | I46: N/ha | J46: m³/ha | K46: cm/an | L46: m³/ha | M46: m³/ha/an | O46: € /ha | P46: € /ha | Q46: € /ha
B47: 0 | C47: 33 | D47: =Ep0B!A$9 -> 17 | E47: =Ep0B!V$9 -> 39.749731 | F47: =Ep0B!A15 -> 53 | G47: =Ep0B!B15 -> 33.792086 | H47: =Ep0B!D15 -> 137.99689 | I47: =Ep0B!C15 -> 284.22 | J47: =Ep0B!F15 -> 604.3065 | K47: =H47/F47 -> 2.6037148 | L47: =Ep0B!T15 -> 1054.7924 | M47: =Ep0B!S15 -> 19.901743 | N47: =Ep0B!U14 -> 78.644888 | O47: =Q47-P47 -> 9733.8502 | P47: =Ep0B!L$32 -> 15794.807 | Q47: =Ep0B!W$32 -> 25528.657
B48: 1 | C48: 30 | D48: =Ep1B!A$9 -> 19 | E48: =Ep1B!V$9 -> 39.749749 | F48: =Ep1B!A15 -> 55 | G48: =Ep1B!B15 -> 31.473855 | H48: =Ep1B!D15 -> 130.55254 | I48: =Ep1B!C15 -> 309.78 | J48: =Ep1B!F15 -> 558.15572 | K48: =H48/F48 -> 2.3736826 | L48: =Ep1B!T15 -> 962.34801 | M48: =Ep1B!S15 -> 17.497237 | N48: =Ep1B!U14 -> 77.428631 | O48: =Q48-P48 -> 8006.0625 | P48: =Ep1B!L$32 -> 13722.38 | Q48: =Ep1B!W$32 -> 21728.442
B49: 2 | C49: 27 | D49: =Ep2B!A$9 -> 22 | E49: =Ep2B!V$9 -> 39.74906 | F49: =Ep2B!A16 -> 64 | G49: =Ep2B!B16 -> 30.903385 | H49: =Ep2B!D16 -> 134.71837 | I49: =Ep2B!C16 -> 288 | J49: =Ep2B!F16 -> 545.39192 | K49: =H49/F49 -> 2.1049745 | L49: =Ep2B!T16 -> 973.74751 | M49: =Ep2B!S16 -> 15.214805 | N49: =Ep2B!U15 -> 73.84723 | O49: =Q49-P49 -> 7741.881 | P49: =Ep2B!L$33 -> 11369.303 | Q49: =Ep2B!W$33 -> 19111.184
...

Sheet Ep0A
D1: Classe de productivité 0, plantation 2.5 x 2 m
A3: Caractéristiques : | E3: Essence : épicéa commun | K3: Plantation : 2.5 x 2 (90% de reprise) | R3: Rotation : 6 ans
E4: Classe 0 (33 m à 50 ans) | K4: Cloisonnement : 1 ligne sur 9 | R4: Taux d'actualisation : 2 %
A5: Table de production
A6: Age | B6: Hdom | C6: Avant prélèvement | G6: Prélèvement | K6: Après prélèvement | O6: Accroissements | U6: h/d | V6: Ecl | W6: Dist
C7: Nha | D7: Cg | E7: Gha | F7: Vha | G7: Nha | H7: Cg | I7: Gha | J7: Vha | K7: Nha | L7: Cg | M7: Gha | N7: Vha | O7: ACC | P7: ACG | Q7: AMG | R7: ACV | S7: AMV | T7: PTV
A8: années | B8: m | C8: N/ha | D8: cm | E8: m²/ha | F8: m³/ha | G8: N/ha | H8: cm | I8: m²/ha | J8: m³/ha | K8: N/ha | L8: cm | M8: m²/ha | N8: m³/ha | O8: cm/ha/an | P8: m²/ha/an | Q8: m²/ha/an | R8: m³/ha/an | S8: m³/ha/an | T8: m³/ha | V8: % | W8: m
A9: 17 | B9: 12.924023 | C9: 1708.955 | D9: 43.572964 | E9: 25.819925 | F9: 149.50424 | G9: 557.855 | H9: 40.649725 | I9: 7.3354489 | J9: 41.052313 | K9: 1151.1 | L9: 44.921265 | M9: 18.484476 | N9: 108.45193 | O9: 2.4830572 | P9: 2.3627046 | Q9: 1.5188191 | R9: 25.226859 | S9: 8.7943671 | T9: 149.50424 | U9: 90.384848 | V9: 32.643048 | W9: 3.1672195
A10: 23 | B10: 17.553035 | C10: 1146.96 | D10: 59.819608 | E10: 32.660703 | F10: 259.81308 | G10: 369.09 | H10: 50.850767 | I10: 7.5948189 | J10: 57.222803 | K10: 777.87 | L10: 63.634544 | M10: 25.065884 | N10: 202.59028 | O10: 2.3564954 | P10: 2.0374384 | Q10: 1.7389631 | R10: 26.766476 | S10: 13.081104 | T10: 300.86539 | U10: 86.658099 | V10: 32.179849 | W10: 3.8528418
A11: 29 | B11: 21.760605 | C11: 774.72 | D11: 77.773517 | E11: 37.290515 | F11: 363.18913 | G11: 212.49 | H11: 67.742328 | I11: 7.7597703 | J11: 73.766658 | K11: 562.23 | L11: 81.242845 | M11: 29.530744 | N11: 289.42248 | O11: 2.2693991 | P11: 1.7654936 | Q11: 1.8007166 | R11: 26.393269 | S11: 15.91256 | T11: 461.46425 | U11: 84.146434 | V11: 27.427974 | W11: 4.5318724
A12: 35 | B12: 25.459632 | C12: 560.34 | D12: 94.859239 | E12: 40.123706 | F12: 447.78209 | G12: 132.03 | H12: 83.922973 | I12: 7.3998767 | J12: 81.538503 | K12: 428.31 | L12: 97.984613 | M12: 32.723829 | N12: 366.24359 | O12: 2.2025054 | P12: 1.5482022 | Q12: 1.7946784 | R12: 25.210738 | S12: 17.709253 | T12: 619.82386 | U12: 81.628933 | V12: 23.56248 | W12: 5.1922498
A13: 41 | B13: 28.679809 | C13: 426.96 | D13: 111.19965 | E13: 42.013043 | F13: 517.50802 | G13: 92.34 | H13: 101.2585 | I13: 7.5343017 | J13: 92.581149 | K13: 334.62 | L13: 113.79015 | M13: 34.478741 | N13: 424.92687 | O13: 2.1613885 | P13: 1.369108 | Q13: 1.7586087 | R13: 23.535644 | S13: 18.807032 | T13: 771.08829 | U13: 79.181085 | V13: 21.627319 | W13: 5.8743354
A14: 47 | B14: 31.434827 | C14: 333.9 | D14: 126.75848 | E14: 42.693389 | F14: 566.14073 | G14: 62.55 | H14: 115.53557 | I14: 6.644294 | J14: 88.047578 | K14: 271.35 | L14: 129.20735 | M14: 36.049095 | N14: 478.09315 | O14: 2.1233914 | P14: 1.2336559 | Q14: 1.7088852 | R14: 22.016476 | S14: 19.410684 | T14: 912.30216 | U14: 76.43174 | V14: 18.733154 | W14: 6.5233363
A15: 53 | B15: 33.818501 | C15: 270.99 | D15: 141.94769 | E15: 43.451031 | F15: 610.19201 | G15: 43.83 | H15: 131.35038 | I15: 6.017613 | J15: 84.828817 | K15: 227.16 | L15: 143.90263 | M15: 37.433418 | N15: 525.36319 | O15: 2.0881448 | P15: 1.1278297 | Q15: 1.6550857 | R15: 20.653303 | S15: 19.70568 | T15: 1044.401 | U15: 73.830444 | V15: 16.174029 | W15: 7.1296589
A16: 59 | B16: 35.86532 | C16: 226.98 | D16: 156.4315 | E16: 44.200396 | F16: 649.28301 | G16: 32.58 | H16: 145.81513 | I16: 5.5124723 | J16: 81.293398 | K16: 194.4 | L16: 158.14101 | M16: 38.687923 | N16: 567.98961 | O16: 2.0594596 | P16: 1.0470285 | Q16: 1.6014664 | R16: 19.519474 | S16: 19.802048 | T16: 1168.3208 | U16: 71.249212 | V16: 14.353688 | W16: 7.7070212
A17: 65 | B17: 37.658007 | C17: 194.4 | D17: 170.49777 | E17: 44.970094 | F17: 685.10646 | G17: 25.2 | H17: 160.015 | I17: 5.1346642 | J17: 78.752541 | K17: 169.2 | L17: 172.00438 | M17: 39.83543 | N17: 606.35392 | O17: 2.0420752 | P17: 0.97955939 | Q17: 1.5502875 | R17: 18.504468 | S17: 19.775964 | T17: 1285.4377 | U17: 68.780876 | V17: 12.962963 | W17: 8.2610358
A18: 71 | B18: 39.223343 | C18: 169.2 | D18: 184.25683 | E18: 45.712786 | F18: 717.38072 | G18: 19.98 | H18: 173.49043 | I18: 4.7856028 | J18: 75.56728 | K18: 149.22 | L18: 185.65102 | M18: 40.927184 | N18: 641.81344 | O18: 2.0318153 | P18: 0.9252493 | Q18: 1.502057 | R18: 17.6573 | S18: 19.668514 | T18: 1396.4645 | U18: 66.373869 | V18: 11.808511 | W18: 8.7967281
A19: 77 | B19: 40.625781 | C19: 149.22 | D19: 197.84191 | E19: 46.478679 | F19: 747.75724 | G19: 16.2 | H19: 188.0402 | I19: 4.5583385 | J19: 73.839621 | K19: 133.02 | L19: 199.00265 | M19: 41.920341 | N19: 673.91762 | O19: 2.0273318 | P19: 0.88022776 | Q19: 1.4571109 | R19: 16.936131 | S19: 19.511796 | T19: 1502.4083 | U19: 64.134651 | V19: 10.856454 | W19: 9.3170025
A20: 83 | B20: 41.889042 | C20: 133.02 | D20: 211.16664 | E20: 47.201707 | F20: 775.53441 | G20: 133.02 | H20: 211.16664 | I20: 47.201707 | J20: 775.53441 | K20: - | L20: - | M20: - | N20: - | O20: - | P20: - | Q20: 1.4154085 | R20: - | S20: 19.325603 | T20: 1604.0251 | U20: 62.319647 | V20: - | W20: -
A22: Distribution des volumes produits par classe de grosseur
A23: Age | B23: Hdom | C23: Classes de grosseur - Volume sur pied | K23: VMV | M23: Classes de grosseur - Volume prélevés | U23: VMP | W23: VMA totale
C24: 20-40 | D24: 40-60 | E24: 60-70 | F24: 70-90 | G24: 90-120 | H24: 120-150 | I24: 150-180 | J24: 180+ | K24: VMV | L24: VMA | M24: 20-40 | N24: 40-60 | O24: 60-70 | P24: 70-90 | Q24: 90-120 | R24: 120-150 | S24: 150-180 | T24: 180+ | U24: VMP | V24: VMA
A25: années | B25: m | C25: m³/ha | D25: m³/ha | E25: m³/ha | F25: m³/ha | G25: m³/ha | H25: m³/ha | I25: m³/ha | J25: m³/ha | K25: € /ha | L25: € /ha | M25: m³/ha | N25: m³/ha | O25: m³/ha | P25: m³/ha | Q25: m³/ha | R25: m³/ha | S25: m³/ha | T25: m³/ha | U25: € /ha | V25: € /ha | W25: € /ha
A26: 17 | B26: 12.924023 | C26: 37.291865 | D26: 98.226724 | E26: 13.729067 | F26: 0 | G26: 0 | H26: 0 | I26: 0 | J26: 0 | K26: 4283.9261 | L26: 3059.4196 | M26: 13.402541 | N26: 24.055293 | O26: 3.3378925 | P26: 0 | Q26: 0 | R26: 0 | S26: 0 | T26: 0 | U26: 761.45121 | V26: 543.79995 | W26: 3059.4196
A27: 23 | B27: 17.553035 | C27: 6.0035091 | D27: 99.472473 | E27: 78.059409 | F27: 76.010977 | G27: 0 | H27: 0 | I27: 0 | J27: 0 | K27: 10531.591 | L27: 6678.6708 | M27: 5.2134811 | N27: 34.655985 | O27: 8.7034184 | P27: 8.3832056 | Q27: 0 | R27: 0 | S27: 0 | T27: 0 | U27: 1559.1577 | V27: 988.74907 | W27: 7222.4707
A28: 29 | B28: 21.760605 | C28: 0.07135981 | D28: 21.623361 | E28: 60.579681 | F28: 202.89444 | G28: 77.670878 | H28: 0 | I28: 0 | J28: 0 | K28: 18656.727 | L28: 10505.832 | M28: 0.07135981 | N28: 16.427351 | O28: 24.95181 | P28: 24.766472 | Q28: 7.2002537 | R28: 0 | S28: 0 | T28: 0 | U28: 2895.8534 | V28: 1630.6907 | W28: 12038.381
A29: 35 | B29: 25.459632 | C29: 0 | D29: 0 | E29: 8.2541946 | F29: 148.69793 | G29: 289.36475 | H29: 1.2301753 | I29: 0 | J29: 0 | K29: 26963.975 | L29: 13482.732 | M29: 0 | N29: 0 | O29: 7.3233633 | P29: 53.758862 | Q29: 20.221239 | R29: 0 | S29: 0 | T29: 0 | U29: 4021.2947 | V29: 2010.7584 | W29: 16645.972
A30: 41 | B30: 28.679809 | C30: 0 | D30: 0 | E30: 0 | F30: 20.086836 | G30: 370.55448 | H30: 126.44627 | I30: 0 | J30: 0 | K30: 34718.982 | L30: 15415.582 | M30: 0 | N30: 0 | O30: 0 | P30: 15.300734 | Q30: 68.14752 | R30: 8.7124645 | S30: 0 | T30: 0 | U30: 5398.2036 | V30: 2396.8575 | W30: 20589.581
A31: 47 | B31: 31.434827 | C31: 0 | D31: 0 | E31: 0 | F31: 0 | G31: 194.33367 | H31: 370.87492 | I31: 0.67164657 | J31: 0 | K31: 40816.686 | L31: 16092.728 | M31: 0 | N31: 0 | O31: 0 | P31: 0 | Q31: 68.43777 | R31: 19.349311 | S31: 0 | T31: 0 | U31: 5635.5207 | V31: 2221.9075 | W31: 23663.583
A32: 53 | B32: 33.818501 | C32: 0 | D32: 0 | E32: 0 | F32: 0 | G32: 16.527869 | H32: 457.28 | I32: 135.97431 | J32: 0 | K32: 46003.032 | L32: 16105.616 | M32: 0 | N32: 0 | O32: 0 | P32: 0 | Q32: 11.688044 | R32: 64.330735 | S32: 8.4002099 | T32: 0 | U32: 5772.6179 | V32: 2020.9879 | W32: 25898.38
A33: 59 | B33: 35.86532 | C33: 0 | D33: 0 | E33: 0 | F33: 0 | G33: 0 | H33: 247.1127 | I33: 401.90132 | J33: 0 | K33: 50083.371 | L33: 15569.814 | M33: 0 | N33: 0 | O33: 0 | P33: 0 | Q33: 0 | R33: 65.414339 | S33: 15.610069 | T33: 0 | U33: 5711.1961 | V33: 1775.4847 | W33: 27383.565
A34: 65 | B34: 37.658007 | C34: 0 | D34: 0 | E34: 0 | F34: 0 | G34: 0 | H34: 25.400515 | I34: 548.48241 | J34: 110.80747 | K34: 53091.456 | L34: 14655.933 | M34: 0 | N34: 0 | O34: 0 | P34: 0 | Q34: 0 | R34: 18.708767 | S34: 54.54089 | T34: 5.0868297 | U34: 5542.9718 | V34: 1530.1412 | W34: 28245.169
A35: 71 | B35: 39.223343 | C35: 0 | D35: 0 | E35: 0 | F35: 0 | G35: 0 | H35: 0 | I35: 352.02342 | J35: 365.06772 | K35: 55053.964 | L35: 13495.109 | M35: 0 | N35: 0 | O35: 0 | P35: 0 | Q35: 0 | R35: 0 | S35: 64.004162 | T35: 11.273531 | U35: 5274.2433 | V35: 1292.8495 | W35: 28614.486
A36: 77 | B36: 40.625781 | C36: 0 | D36: 0 | E36: 0 | F36: 0 | G36: 0 | H36: 0 | I36: 47.695822 | J36: 699.75124 | K36: 56066.857 | L36: 12203.741 | M36: 0 | N36: 0 | O36: 0 | P36: 0 | Q36: 0 | R36: 0 | S36: 21.75747 | T36: 51.77197 | U36: 5010.5719 | V36: 1090.6215 | W36: 28615.967
A37: 83 | B37: 41.889042 | C37: 0 | D37: 0 | E37: 0 | F37: 0 | G37: 0 | H37: 0 | I37: 0 | J37: 775.53441 | K37: 56193.579 | L37: 10861.066 | M37: 0 | N37: 0 | O37: 0 | P37: 0 | Q37: 0 | R37: 0 | S37: 0 | T37: 775.53441 | U37: 56193.579 | V37: 10861.066 | W37: 28363.914
A38: Total | B38: - | C38: - | D38: - | E38: - | F38: - | G38: - | H38: - | I38: - | J38: - | K38: - | L38: - | M38: 18.687382 | N38: 75.138628 | O38: 44.316484 | P38: 102.20927 | Q38: 175.69483 | R38: 176.51562 | S38: 164.3128 | T38: 843.66674 | U38: - | V38: 28363.914 | W38: -
W40: J. Perin, 2016
W41: (j.perin@ulg.ac.be)

Sheet Ep1A
D1: Classe de productivité 1, plantation 2.5 x 2 m
A3: Caractéristiques : | E3: Essence : épicéa commun | K3: Plantation : 2.5 x 2 (90% de reprise) | R3: Rotation : 6 ans
E4: Classe I (30 m à 50 ans) | K4: Cloisonnement : 1 ligne sur 9 | R4: Taux d'actualisation : 2 %
A5: Table de production
A6: Age | B6: Hdom | C6: Avant prélèvement | G6: Prélèvement | K6: Après prélèvement | O6: Accroissements | U6: h/d | V6: Ecl | W6: Dist
C7: Nha | D7: Cg | E7: Gha | F7: Vha | G7: Nha | H7: Cg | I7: Gha | J7: Vha | K7: Nha | L7: Cg | M7: Gha | N7: Vha | O7: ACC | P7: ACG | Q7: AMG | R7: ACV | S7: AMV | T7: PTV
A8: années | B8: m | C8: N/ha | D8: cm | E8: m²/ha | F8: m³/ha | G8: N/ha | H8: cm | I8: m²/ha | J8: m³/ha | K8: N/ha | L8: cm | M8: m²/ha | N8: m³/ha | O8: cm/ha/an | P8: m²/ha/an | Q8: m²/ha/an | R8: m³/ha/an | S8: m³/ha/an | T8: m³/ha | V8: % | W8: m
A9: 19 | B9: 13.055091 | C9: 1708.765 | D9: 44.16699 | E9: 26.525775 | F9: 155.65576 | G9: 557.845 | H9: 41.230158 | I9: 7.5462934 | J9: 42.873725 | K9: 1150.92 | L9: 45.522335 | M9: 18.979481 | N9: 112.78204 | O9: 2.2414104 | P9: 2.1297257 | Q9: 1.3960934 | R9: 22.497598 | S9: 8.1924086 | T9: 155.65576 | U9: 90.095947 | V9: 32.646092 | W9: 3.1674671
A10: 25 | B10: 17.141177 | C10: 1147.59 | D10: 58.970798 | E10: 31.757836 | F10: 247.76763 | G10: 343.98 | H10: 50.071766 | I10: 6.8629233 | J10: 50.61591 | K10: 803.61 | L10: 62.393244 | M10: 24.894912 | N10: 197.15172 | O10: 2.1325374 | P10: 1.8580393 | Q10: 1.5721652 | R10: 23.61399 | S10: 11.625654 | T10: 290.64135 | U10: 86.308376 | V10: 29.97412 | W10: 3.7906354
A11: 31 | B11: 20.832858 | C11: 801.18 | D11: 75.188469 | E11: 36.043148 | F11: 338.83566 | G11: 204.21 | H11: 65.080811 | I11: 6.8829252 | J11: 62.870765 | K11: 596.97 | L11: 78.347311 | M11: 29.160223 | N11: 275.96489 | O11: 2.0562263 | P11: 1.6285569 | Q11: 1.6274956 | R11: 23.304678 | S11: 13.945977 | T11: 432.32529 | U11: 83.536185 | V11: 25.488654 | W11: 4.3980325
A12: 37 | B12: 24.083262 | C12: 594.9 | D12: 90.684669 | E12: 38.931564 | F12: 415.79296 | G12: 131.94 | H12: 80.12662 | I12: 6.7409369 | J12: 71.04296 | K12: 462.96 | L12: 93.475526 | M12: 32.190627 | N12: 344.75 | O12: 1.9981432 | P12: 1.4445604 | Q12: 1.6276677 | R12: 22.34554 | S12: 15.463604 | T12: 572.15336 | U12: 80.940758 | V12: 22.178517 | W12: 4.9941657
A13: 43 | B13: 26.902152 | C13: 461.61 | D13: 105.46439 | E13: 40.85799 | F13: 478.82324 | G13: 97.02 | H13: 95.197945 | I13: 6.9969143 | J13: 81.604504 | K13: 364.59 | L13: 108.03213 | M13: 33.861075 | N13: 397.21874 | O13: 1.9672079 | P13: 1.2868382 | Q13: 1.6021179 | R13: 20.940734 | S13: 16.423874 | T13: 706.2266 | U13: 78.231915 | V13: 21.017742 | W13: 5.6277177
A14: 49 | B14: 29.338228 | C14: 363.87 | D14: 119.83537 | E14: 41.582104 | F14: 522.86314 | G14: 65.52 | H14: 109.46513 | I14: 6.2476341 | J14: 78.456807 | K14: 298.35 | L14: 121.99477 | M14: 35.33447 | N14: 444.40634 | O14: 1.9366685 | P14: 1.1646443 | Q14: 1.5635122 | R14: 19.645996 | S14: 16.976959 | T14: 831.87101 | U14: 75.551404 | V14: 18.006431 | W14: 6.2211642
A15: 55 | B15: 31.457775 | C15: 297.9 | D15: 133.61478 | E15: 42.322336 | F15: 562.28231 | G15: 46.71 | H15: 123.62115 | I15: 5.6804869 | J15: 75.645773 | K15: 251.19 | L15: 135.39183 | M15: 36.641849 | N15: 486.63654 | O15: 1.9070139 | P15: 1.0706812 | Q15: 1.5199993 | R15: 18.523446 | S15: 17.268127 | T15: 949.74698 | U15: 72.993708 | V15: 15.679758 | W15: 6.7800596
A16: 61 | B16: 33.301142 | C16: 251.01 | D16: 146.83391 | E16: 43.065936 | F16: 597.77722 | G16: 35.28 | H16: 136.40518 | I16: 5.2237267 | J16: 72.754334 | K16: 215.73 | L16: 148.46972 | M16: 37.84221 | N16: 525.02288 | O16: 1.8851935 | P16: 0.99760947 | Q16: 1.4758041 | R16: 17.579869 | S16: 17.391601 | T16: 1060.8877 | U16: 70.464617 | V16: 14.055217 | W16: 7.3160963
A17: 67 | B17: 34.926914 | C17: 215.73 | D17: 159.78089 | E17: 43.827866 | F17: 630.5021 | G17: 27.09 | H17: 150.56364 | I17: 4.8869661 | J17: 70.777078 | K17: 188.64 | L17: 161.06124 | M17: 38.9409 | N17: 559.72502 | O17: 1.8709846 | P17: 0.93625142 | Q17: 1.4329807 | R17: 16.73639 | S17: 17.408461 | T17: 1166.3669 | U17: 68.126966 | V17: 12.557363 | W17: 7.8238009
A18: 73 | B18: 36.359597 | C18: 188.64 | D18: 172.28715 | E18: 44.558409 | F18: 660.14336 | G18: 21.87 | H18: 162.36841 | I18: 4.5881965 | J18: 68.385494 | K18: 166.77 | L18: 173.54583 | M18: 39.970212 | N18: 591.75787 | O18: 1.8638271 | P18: 0.88619594 | Q18: 1.3921536 | R18: 16.026654 | S18: 17.353222 | T18: 1266.7852 | U18: 65.819524 | V18: 11.593511 | W18: 8.3210038
A19: 79 | B19: 37.658007 | C19: 166.77 | D19: 184.7288 | E19: 45.287388 | F19: 687.91779 | G19: 17.64 | H19: 176.09099 | I19: 4.3527429 | J19: 66.675306 | K19: 149.13 | L19: 185.72396 | M19: 40.934645 | N19: 621.24249 | O19: 1.8606296 | P19: 0.8448378 | Q19: 1.3537265 | R19: 15.427924 | S19: 17.25247 | T19: 1362.9451 | U19: 63.699976 | V19: 10.577442 | W19: 8.7993821
A20: 85 | B20: 38.830975 | C20: 149.13 | D20: 196.88774 | E20: 46.003672 | F20: 713.81003 | G20: 149.13 | H20: 196.88774 | I20: 46.003672 | J20: 713.81003 | K20: - | L20: - | M20: - | N20: - | O20: - | P20: - | Q20: 1.3178049 | R20: - | S20: 17.123679 | T20: 1455.5127 | U20: 61.959727 | V20: - | W20: -
A22: Distribution des volumes produits par classe de grosseur
A23: Age | B23: Hdom | C23: Classes de grosseur - Volume sur pied | K23: VMV | M23: Classes de grosseur - Volume prélevés | U23: VMP | W23: VMA totale
C24: 20-40 | D24: 40-60 | E24: 60-70 | F24: 70-90 | G24: 90-120 | H24: 120-150 | I24: 150-180 | J24: 180+ | K24: VMV | L24: VMA | M24: 20-40 | N24: 40-60 | O24: 60-70 | P24: 70-90 | Q24: 90-120 | R24: 120-150 | S24: 150-180 | T24: 180+ | U24: VMP | V24: VMA
A25: années | B25: m | C25: m³/ha | D25: m³/ha | E25: m³/ha | F25: m³/ha | G25: m³/ha | H25: m³/ha | I25: m³/ha | J25: m³/ha | K25: € /ha | L25: € /ha | M25: m³/ha | N25: m³/ha | O25: m³/ha | P25: m³/ha | Q25: m³/ha | R25: m³/ha | S25: m³/ha | T25: m³/ha | U25: € /ha | V25: € /ha | W25: € /ha
A26: 19 | B26: 13.055091 | C26: 36.197153 | D26: 102.65972 | E26: 16.531164 | F26: 0 | G26: 0 | H26: 0 | I26: 0 | J26: 0 | K26: 4533.4053 | L26: 3111.8689 | M26: 13.370501 | N26: 25.487333 | O26: 3.7481682 | P26: 0 | Q26: 0 | R26: 0 | S26: 0 | T26: 0 | U26: 823.07587 | V26: 564.9846 | W26: 3111.8689
A27: 25 | B27: 17.141177 | C27: 6.2728695 | D27: 101.11573 | E27: 77.098092 | F27: 63.038438 | G27: 0 | H27: 0 | I27: 0 | J27: 0 | K27: 9879.7939 | L27: 6022.0394 | M27: 5.1393124 | N27: 30.296252 | O27: 8.020644 | P27: 6.9172 | Q27: 0 | R27: 0 | S27: 0 | T27: 0 | U27: 1347.4694 | V27: 821.32421 | W27: 6587.024
A28: 31 | B28: 20.832858 | C28: 0.13094694 | D28: 28.060855 | E28: 71.443137 | F28: 187.07679 | G28: 51.865784 | H28: 0 | I28: 0 | J28: 0 | K28: 16878.966 | L28: 9135.6721 | M28: 0.13094694 | N28: 19.033905 | O28: 21.769159 | P28: 17.631001 | Q28: 4.047606 | R28: 0 | S28: 0 | T28: 0 | U28: 2345.5442 | V28: 1269.5164 | W28: 10521.981
A29: 37 | B29: 24.083262 | C29: 0 | D29: 1.0782262 | E29: 13.954357 | F29: 179.65485 | G29: 220.77857 | H29: 0 | I29: 0 | J29: 0 | K29: 24167.618 | L29: 11615.222 | M29: 0 | N29: 1.0782262 | O29: 10.716818 | P29: 43.556428 | Q29: 15.364537 | R29: 0 | S29: 0 | T29: 0 | U29: 3338.278 | V29: 1604.4129 | W29: 14271.047
A30: 43 | B30: 26.902152 | C30: 0 | D30: 0 | E30: 0 | F30: 45.422832 | G30: 373.11556 | H30: 59.92037 | I30: 0 | J30: 0 | K30: 31037.251 | L30: 13245.729 | M30: 0 | N30: 0 | O30: 0 | P30: 29.730654 | Q30: 47.153869 | R30: 4.3555018 | S30: 0 | T30: 0 | U30: 4517.9473 | V30: 1928.1187 | W30: 17505.967
A31: 49 | B31: 29.338228 | C31: 0 | D31: 0 | E31: 0 | F31: 0.36929561 | G31: 294.66122 | H31: 227.56073 | I31: 0 | J31: 0 | K31: 36629.075 | L31: 13880.897 | M31: 0 | N31: 0 | O31: 0 | P31: 0.36929561 | Q31: 65.733697 | R31: 12.081925 | S31: 0 | T31: 0 | U31: 4845.9858 | V31: 1836.4272 | W31: 20069.254
A32: 55 | B32: 31.457775 | C32: 0 | D32: 0 | E32: 0 | F32: 0 | G32: 78.361227 | H32: 443.74526 | I32: 39.852676 | J32: 0 | K32: 41485.736 | L32: 13960.126 | M32: 0 | N32: 0 | O32: 0 | P32: 0 | Q32: 36.926116 | R32: 36.764139 | S32: 1.6323666 | T32: 0 | U32: 5018.5998 | V32: 1688.7802 | W32: 21984.91
A33: 61 | B33: 33.301142 | C33: 0 | D33: 0 | E33: 0 | F33: 0 | G33: 0.44194991 | H33: 405.13152 | I33: 191.93946 | J33: 0 | K33: 45528.328 | L33: 13604.144 | M33: 0 | N33: 0 | O33: 0 | P33: 0 | Q33: 0.44194991 | R33: 64.741944 | S33: 7.3061521 | T33: 0 | U33: 5028.7751 | V33: 1502.6289 | W33: 23317.708
A34: 67 | B34: 34.926914 | C34: 0 | D34: 0 | E34: 0 | F34: 0 | G34: 0 | H34: 179.56107 | I34: 450.17365 | J34: 0.34691625 | K34: 48761.64 | L34: 12937.989 | M34: 0 | N34: 0 | O34: 0 | P34: 0 | Q34: 0 | R34: 50.703126 | S34: 19.653486 | T34: 0 | U34: 4973.5394 | V34: 1319.6357 | W34: 24154.182
A35: 73 | B35: 36.359597 | C35: 0 | D35: 0 | E35: 0 | F35: 0 | G35: 0 | H35: 9.4904805 | I35: 524.02919 | J35: 126.33009 | K35: 51156.249 | L35: 12052.75 | M35: 0 | N35: 0 | O35: 0 | P35: 0 | Q35: 0 | R35: 7.7625748 | S35: 56.187232 | T35: 4.1420767 | U35: 4822.7547 | V35: 1136.2729 | W35: 24588.579
A36: 79 | B36: 37.658007 | C36: 0 | D36: 0 | E36: 0 | F36: 0 | G36: 0 | H36: 0 | I36: 336.52351 | J36: 350.96617 | K36: 52757.715 | L36: 11037.543 | M36: 0 | N36: 0 | O36: 0 | P36: 0 | Q36: 0 | R36: 0 | S36: 52.946226 | T36: 13.300973 | U36: 4617.7306 | V36: 966.08431 | W36: 24709.645
A37: 85 | B37: 38.830975 | C37: 0 | D37: 0 | E37: 0 | F37: 0 | G37: 0 | H37: 0 | I37: 57.306041 | J37: 656.50399 | K37: 53657.039 | L37: 9968.0935 | M37: 0 | N37: 0 | O37: 0 | P37: 0 | Q37: 0 | R37: 0 | S37: 57.306041 | T37: 656.50399 | U37: 53657.039 | V37: 9968.0935 | W37: 24606.279
A38: Total | B38: - | C38: - | D38: - | E38: - | F38: - | G38: - | H38: - | I38: - | J38: - | K38: - | L38: - | M38: 18.64076 | N38: 75.895716 | O38: 44.254789 | P38: 98.204578 | Q38: 169.66777 | R38: 176.40921 | S38: 195.0315 | T38: 673.94704 | U38: - | V38: 24606.279 | W38: -
W40: J. Perin, 2016
W41: (j.perin@ulg.ac.be)

Sheet Ep2A
D1: Classe de productivité 2, plantation 2.5 x 2 m
A3: Caractéristiques : | E3: Essence : épicéa commun | K3: Plantation : 2.5 x 2 (90% de reprise) | R3: Rotation : 6 ans
E4: Classe II (27 m à 50 ans) | K4: Cloisonnement : 1 ligne sur 9 | R4: Taux d'actualisation : 2 %
A5: Table de production
A6: Age | B6: Hdom | C6: Avant prélèvement | G6: Prélèvement | K6: Après prélèvement | O6: Accroissements | U6: h/d | V6: Ecl | W6: Dist
C7: Nha | D7: Cg | E7: Gha | F7: Vha | G7: Nha | H7: Cg | I7: Gha | J7: Vha | K7: Nha | L7: Cg | M7: Gha | N7: Vha | O7: ACC | P7: ACG | Q7: AMG | R7: ACV | S7: AMV | T7: PTV
A8: années | B8: m | C8: N/ha | D8: cm | E8: m²/ha | F8: m³/ha | G8: N/ha | H8: cm | I8: m²/ha | J8: m³/ha | K8: N/ha | L8: cm | M8: m²/ha | N8: m³/ha | O8: cm/ha/an | P8: m²/ha/an | Q8: m²/ha/an | R8: m³/ha/an | S8: m³/ha/an | T8: m³/ha | V8: % | W8: m
A9: 22 | B9: 13.484545 | C9: 1707.625 | D9: 45.604162 | E9: 28.261265 | F9: 171.84894 | G9: 557.425 | H9: 42.451594 | I9: 7.9940083 | J9: 47.074478 | K9: 1150.2 | L9: 47.056079 | M9: 20.267257 | N9: 124.77446 | O9: 1.9517704 | P9: 1.8768733 | Q9: 1.284603 | R9: 19.934906 | S9: 7.8113153 | T9: 171.84894 | U9: 90.026515 | V9: 32.643291 | W9: 3.1684583
A10: 28 | B10: 16.993537 | C10: 1147.23 | D10: 58.766701 | E10: 31.528496 | F10: 244.38389 | G10: 340.2 | H10: 49.58758 | I10: 6.6568729 | J10: 48.567343 | K10: 807.03 | L10: 62.231771 | M10: 24.871623 | N10: 195.81655 | O10: 1.9054463 | P10: 1.6474225 | Q10: 1.411518 | R10: 20.418166 | S10: 10.409228 | T10: 291.45837 | U10: 85.787001 | V10: 29.654036 | W10: 3.782595
A11: 34 | B11: 20.149074 | C11: 804.87 | D11: 73.664449 | E11: 34.756158 | F11: 318.32555 | G11: 182.34 | H11: 63.507668 | I11: 5.8522709 | J11: 52.007366 | K11: 622.53 | L11: 76.384091 | M11: 28.903887 | N11: 266.31818 | O11: 1.8317738 | P11: 1.4687136 | Q11: 1.4531482 | R11: 20.186498 | S11: 12.175511 | T11: 413.96737 | U11: 82.870898 | V11: 22.65459 | W11: 4.3067984
A12: 40 | B12: 22.916098 | C12: 620.82 | D12: 87.374734 | E12: 37.716169 | F12: 387.43717 | G12: 126.72 | H12: 76.944064 | I12: 5.970154 | J12: 60.345144 | K12: 494.1 | L12: 89.854972 | M12: 31.746015 | N12: 327.09203 | O12: 1.7851574 | P12: 1.3196825 | Q12: 1.455483 | R12: 19.438798 | S12: 13.377159 | T12: 535.08636 | U12: 80.121382 | V12: 20.411714 | W12: 4.8342294
A13: 46 | B13: 25.335678 | C13: 492.84 | D13: 100.56592 | E13: 39.66411 | F13: 443.72482 | G13: 98.1 | H13: 90.318179 | I13: 6.3680944 | J13: 70.689868 | K13: 394.74 | L13: 102.95454 | M13: 33.296015 | N13: 373.03495 | O13: 1.7668638 | P13: 1.1878104 | Q13: 1.4377699 | R13: 18.320963 | S13: 14.167808 | T13: 651.71915 | U13: 77.310219 | V13: 19.90504 | W13: 5.4085284
A14: 52 | B14: 27.445912 | C14: 393.93 | D14: 113.55572 | E14: 40.422878 | F14: 482.96073 | G14: 67.41 | H14: 103.6493 | I14: 5.7629814 | J14: 68.682171 | K14: 326.52 | L14: 115.49513 | M14: 34.659897 | N14: 414.27856 | O14: 1.7432072 | P14: 1.0841737 | Q14: 1.4089284 | R14: 17.290026 | S14: 14.647018 | T14: 761.64493 | U14: 74.655855 | V14: 17.112177 | W14: 5.9467515
A15: 58 | B15: 29.29464 | C15: 326.07 | D15: 125.95437 | E15: 41.164939 | F15: 518.01871 | G15: 49.32 | H15: 115.86854 | I15: 5.2691951 | J15: 66.331733 | K15: 276.75 | L15: 127.66816 | M15: 35.895744 | N15: 451.68698 | O15: 1.7243399 | P15: 1.0021143 | Q15: 1.3753331 | R15: 16.384622 | S15: 14.920432 | T15: 865.38508 | U15: 72.086748 | V15: 15.125587 | W15: 6.4593805
A16: 64 | B16: 30.92649 | C16: 276.48 | D16: 138.0142 | E16: 41.90843 | F16: 549.99471 | G16: 37.62 | H16: 127.64699 | I16: 4.8778681 | J16: 64.16137 | K16: 238.86 | L16: 139.57684 | M16: 37.030562 | N16: 485.83334 | O16: 1.7084442 | P16: 0.93980862 | Q16: 1.3403439 | R16: 15.653383 | S16: 15.0577 | T16: 963.69281 | U16: 69.60928 | V16: 13.606771 | W16: 6.9528518
A17: 70 | B17: 32.381281 | C17: 238.86 | D17: 149.82751 | E17: 42.669414 | F17: 579.75364 | G17: 29.16 | H17: 140.87942 | I17: 4.6054571 | J17: 62.866668 | K17: 209.7 | L17: 151.02981 | M17: 38.063957 | N17: 516.88697 | O17: 1.699637 | P17: 0.88564065 | Q17: 1.3060123 | R17: 14.982256 | S17: 15.108759 | T17: 1057.6131 | U17: 67.356764 | V17: 12.207988 | W17: 7.4205393
A18: 76 | B18: 33.68772 | C18: 209.7 | D18: 161.22763 | E18: 43.3778 | F18: 606.78051 | G18: 23.49 | H18: 152.51356 | I18: 4.3480052 | J18: 61.235401 | K18: 186.21 | L18: 162.29367 | M18: 39.029795 | N18: 545.54511 | O18: 1.6954124 | P18: 0.84101122 | Q18: 1.272825 | R18: 14.413679 | S18: 15.098772 | T18: 1147.5067 | U18: 65.210859 | V18: 11.201717 | W18: 7.8746849
A19: 82 | B19: 34.872847 | C19: 186.21 | D19: 172.46614 | E19: 44.075863 | F19: 632.02718 | G19: 19.53 | H19: 162.49671 | I19: 4.1037561 | J19: 59.215065 | K19: 166.68 | L19: 173.5968 | M19: 39.972107 | N19: 572.81212 | O19: 1.6960507 | P19: 0.80395257 | Q19: 1.2412289 | R19: 13.940188 | S19: 15.048643 | T19: 1233.9887 | U19: 63.10962 | V19: 10.488159 | W19: 8.32325
A20: 88 | B20: 35.973871 | C20: 166.68 | D20: 183.7731 | E20: 44.795822 | F20: 656.45324 | G20: 166.68 | H20: 183.7731 | I20: 44.795822 | J20: 656.45324 | K20: - | L20: - | M20: - | N20: - | O20: - | P20: - | Q20: 1.2114146 | R20: - | S20: 14.973066 | T20: 1317.6298 | U20: 61.497167 | V20: - | W20: -
A22: Distribution des volumes produits par classe de grosseur
A23: Age | B23: Hdom | C23: Classes de grosseur - Volume sur pied | K23: VMV | M23: Classes de grosseur - Volume prélevés | U23: VMP | W23: VMA totale
C24: 20-40 | D24: 40-60 | E24: 60-70 | F24: 70-90 | G24: 90-120 | H24: 120-150 | I24: 150-180 | J24: 180+ | K24: VMV | L24: VMA | M24: 20-40 | N24: 40-60 | O24: 60-70 | P24: 70-90 | Q24: 90-120 | R24: 120-150 | S24: 150-180 | T24: 180+ | U24: VMP | V24: VMA
A25: années | B25: m | C25: m³/ha | D25: m³/ha | E25: m³/ha | F25: m³/ha | G25: m³/ha | H25: m³/ha | I25: m³/ha | J25: m³/ha | K25: € /ha | L25: € /ha | M25: m³/ha | N25: m³/ha | O25: m³/ha | P25: m³/ha | Q25: m³/ha | R25: m³/ha | S25: m³/ha | T25: m³/ha | U25: € /ha | V25: € /ha | W25: € /ha
A26: 22 | B26: 13.484545 | C26: 33.175992 | D26: 113.69306 | E26: 24.685749 | F26: 0 | G26: 0 | H26: 0 | I26: 0 | J26: 0 | K26: 5199.4386 | L26: 3363.1998 | M26: 13.236439 | N26: 27.711819 | O26: 5.8320854 | P26: 0 | Q26: 0 | R26: 0 | S26: 0 | T26: 0 | U26: 950.6284 | V26: 614.90356 | W26: 3363.1998
A27: 28 | B27: 16.993537 | C27: 6.5812522 | D27: 100.71705 | E27: 74.455789 | F27: 62.440594 | G27: 0 | H27: 0 | I27: 0 | J27: 0 | K27: 9711.2023 | L27: 5577.8675 | M27: 5.4402931 | N27: 29.345007 | O27: 7.90612 | P27: 5.6867181 | Q27: 0 | R27: 0 | S27: 0 | T27: 0 | U27: 1266.8903 | V27: 727.66957 | W27: 6192.771
A28: 34 | B28: 20.149074 | C28: 0.28303473 | D28: 31.261932 | E28: 75.533615 | F28: 173.67146 | G28: 37.298889 | H28: 0 | I28: 0 | J28: 0 | K28: 15550.047 | L28: 7930.9619 | M28: 0.28303473 | N28: 18.635223 | O28: 16.65075 | P28: 12.865848 | Q28: 3.2958935 | R28: 0 | S28: 0 | T28: 0 | U28: 1882.3031 | V28: 960.02758 | W28: 9273.5351
A29: 40 | B29: 22.916098 | C29: 0 | D29: 2.5604854 | E29: 20.660386 | F29: 195.07527 | G29: 168.89112 | H29: 0 | I29: 0 | J29: 0 | K29: 21853.408 | L29: 9897.1992 | M29: 0 | N29: 2.3597996 | O29: 13.064344 | P29: 33.40529 | Q29: 11.265799 | R29: 0 | S29: 0 | T29: 0 | U29: 2714.7797 | V29: 1229.4977 | W29: 12199.8
A30: 46 | B30: 25.335678 | C30: 0 | D30: 0 | E30: 0.78399922 | F30: 84.760192 | G30: 337.03487 | H30: 20.887194 | I30: 0 | J30: 0 | K30: 27832.949 | L30: 11193.124 | M30: 0 | N30: 0 | O30: 0.78399922 | P30: 40.129393 | Q30: 28.129769 | R30: 1.3881432 | S30: 0 | T30: 0 | U30: 3734.654 | V30: 1501.905 | W30: 14725.223
A31: 52 | B31: 27.445912 | C31: 0 | D31: 0 | E31: 0 | F31: 6.2920521 | G31: 343.7047 | H31: 132.71411 | I31: 0 | J31: 0 | K31: 32804.704 | L31: 11714.593 | M31: 0 | N31: 0 | O31: 0 | P31: 5.1887987 | Q31: 57.073622 | R31: 6.1698807 | S31: 0 | T31: 0 | U31: 4076.5833 | V31: 1455.752 | W31: 16748.596
A32: 58 | B32: 29.29464 | C32: 0 | D32: 0 | E32: 0 | F32: 0 | G32: 192.60327 | H32: 325.1755 | I32: 0 | J32: 0 | K32: 37232.736 | L32: 11806.332 | M32: 0 | N32: 0 | O32: 0 | P32: 0 | Q32: 50.573002 | R32: 15.518794 | S32: 0 | T32: 0 | U32: 4250.1261 | V32: 1347.6957 | W32: 18296.087
A33: 64 | B33: 30.92649 | C33: 0 | D33: 0 | E33: 0 | F33: 0 | G33: 27.667903 | H33: 453.10259 | I33: 68.994896 | J33: 0 | K33: 41097.745 | L33: 11571.962 | M33: 0 | N33: 0 | O33: 0 | P33: 0 | Q33: 16.955317 | R33: 44.85402 | S33: 2.1227094 | T33: 0 | U33: 4325.1288 | V33: 1217.8339 | W33: 19409.413
A34: 70 | B34: 32.381281 | C34: 0 | D34: 0 | E34: 0 | F34: 0 | G34: 0.14054096 | H34: 350.80081 | I34: 228.52977 | J34: 0 | K34: 44381.633 | L34: 11096.634 | M34: 0 | N34: 0 | O34: 0 | P34: 0 | Q34: 0.14054096 | R34: 52.692811 | S34: 9.7507913 | T34: 0 | U34: 4379.1826 | V34: 1094.9166 | W34: 20151.919
A35: 76 | B35: 33.68772 | C35: 0 | D35: 0 | E35: 0 | F35: 0 | G35: 0 | H35: 138.5338 | I35: 462.47626 | J35: 5.4133747 | K35: 46982.468 | L35: 10430.924 | M35: 0 | N35: 0 | O35: 0 | P35: 0 | Q35: 0 | R35: 41.875946 | S35: 19.002373 | T35: 0 | U35: 4310.2042 | V35: 956.94018 | W35: 20581.125
A36: 82 | B36: 34.872847 | C36: 0 | D36: 0 | E36: 0 | F36: 0 | G36: 0 | H36: 6.3417905 | I36: 505.51114 | J36: 119.91262 | K36: 48987.488 | L36: 9657.6416 | M36: 0 | N36: 0 | O36: 0 | P36: 0 | Q36: 0 | R36: 3.4972871 | S36: 51.42191 | T36: 4.0342364 | U36: 4175.1445 | V36: 823.10915 | W36: 20764.783
A37: 88 | B37: 35.973871 | C37: 0 | D37: 0 | E37: 0 | F37: 0 | G37: 0 | H37: 0 | I37: 338.35741 | J37: 318.09583 | K37: 50451.273 | L37: 8831.9583 | M37: 0 | N37: 0 | O37: 0 | P37: 0 | Q37: 0 | R37: 0 | S37: 338.35741 | T37: 318.09583 | U37: 50451.273 | V37: 8831.9583 | W37: 20762.209
A38: Total | B38: - | C38: - | D38: - | E38: - | F38: - | G38: - | H38: - | I38: - | J38: - | K38: - | L38: - | M38: 18.959767 | N38: 78.051849 | O38: 44.237299 | P38: 97.276049 | Q38: 167.43394 | R38: 165.99688 | S38: 420.65519 | T38: 322.13007 | U38: - | V38: 20762.209 | W38: -
W40: J. Perin, 2016
W41: (j.perin@ulg.ac.be)

Sheet Ep3A
D1: Classe de productivité 3, plantation 2.5 x 2 m
A3: Caractéristiques : | E3: Essence : épicéa commun | K3: Plantation : 2.5 x 2 (90% de reprise) | R3: Rotation : 6 ans
E4: Classe III (24 m à 50 ans) | K4: Cloisonnement : 1 ligne sur 9 | R4: Taux d'actualisation : 2 %
A5: Table de production
A6: Age | B6: Hdom | C6: Avant prélèvement | G6: Prélèvement | K6: Après prélèvement | O6: Accroissements | U6: h/d | V6: Ecl | W6: Dist
C7: Nha | D7: Cg | E7: Gha | F7: Vha | G7: Nha | H7: Cg | I7: Gha | J7: Vha | K7: Nha | L7: Cg | M7: Gha | N7: Vha | O7: ACC | P7: ACG | Q7: AMG | R7: ACV | S7: AMV | T7: PTV
A8: années | B8: m | C8: N/ha | D8: cm | E8: m²/ha | F8: m³/ha | G8: N/ha | H8: cm | I8: m²/ha | J8: m³/ha | K8: N/ha | L8: cm | M8: m²/ha | N8: m³/ha | O8: cm/ha/an | P8: m²/ha/an | Q8: m²/ha/an | R8: m³/ha/an | S8: m³/ha/an | T8: m³/ha | V8: % | W8: m
A9: 25 | B9: 13.421578 | C9: 1707.91 | D9: 45.471295 | E9: 28.101516 | F9: 170.19792 | G9: 557.53 | H9: 42.478072 | I9: 8.0054908 | J9: 47.112896 | K9: 1150.38 | L9: 46.853211 | M9: 20.096025 | N9: 123.08503 | O9: 1.7265302 | P9: 1.636594 | Q9: 1.1240607 | R9: 16.93469 | S9: 6.8079169 | T9: 170.19792 | U9: 89.994111 | V9: 32.643992 | W9: 3.1682105
A10: 31 | B10: 16.383631 | C10: 1148.49 | D10: 57.212392 | E10: 29.91559 | F10: 224.69317 | G10: 293.13 | H10: 47.883021 | I10: 5.348272 | J10: 37.585931 | K10: 855.36 | L10: 60.077152 | M10: 24.567318 | N10: 187.10724 | O10: 1.6700058 | P10: 1.4679995 | Q10: 1.2232607 | R10: 17.420772 | S10: 8.7679375 | T10: 271.80606 | U10: 85.674325 | V10: 25.523078 | W10: 3.6741782
A11: 37 | B11: 19.053064 | C11: 853.56 | D11: 70.097187 | E11: 33.375314 | F11: 291.63187 | G11: 175.59 | H11: 59.759559 | I11: 4.9900475 | J11: 41.928572 | K11: 677.97 | L11: 72.534761 | M11: 28.385267 | N11: 249.7033 | O11: 1.6088704 | P11: 1.3300986 | Q11: 1.262948 | R11: 17.329191 | S11: 10.1711 | T11: 376.33069 | U11: 82.521764 | V11: 20.571489 | W11: 4.1269523
A12: 43 | B12: 21.415873 | C12: 676.53 | D12: 82.187984 | E12: 36.365859 | F12: 353.67844 | G12: 128.52 | H12: 72.026019 | I12: 5.3056631 | J12: 50.593466 | K12: 548.01 | L12: 84.394236 | M12: 31.060196 | N12: 303.08497 | O12: 1.5742442 | P12: 1.2078378 | Q12: 1.2723179 | R12: 16.774984 | S12: 11.169903 | T12: 480.30584 | U12: 79.721023 | V12: 18.99694 | W12: 4.5902934
A13: 49 | B13: 23.48685 | C13: 546.66 | D13: 93.839701 | E13: 38.307222 | F13: 403.73488 | G13: 103.95 | H13: 83.835623 | I13: 5.813957 | J13: 60.685744 | K13: 442.71 | L13: 96.037743 | M13: 32.493265 | N13: 343.04914 | O13: 1.5635845 | P13: 1.099107 | Q13: 1.2644224 | R13: 15.931322 | S13: 11.85624 | T13: 580.95575 | U13: 76.83033 | V13: 19.015476 | W13: 5.1071077
A14: 55 | B14: 25.305497 | C14: 441.99 | D14: 105.41925 | E14: 39.087908 | F14: 438.63707 | G14: 73.53 | H14: 95.185174 | I14: 5.3014335 | J14: 59.148265 | K14: 368.46 | L14: 107.34485 | M14: 33.786474 | N14: 379.4888 | O14: 1.5507546 | P14: 1.0103773 | Q14: 1.246388 | R14: 15.134079 | S14: 12.300794 | T14: 676.54367 | U14: 74.059972 | V14: 16.636123 | W14: 5.5980853
A15: 61 | B15: 26.927701 | C15: 368.01 | D15: 116.64937 | E15: 39.848738 | F15: 470.29328 | G15: 53.73 | H15: 107.14932 | I15: 4.908918 | J15: 57.958198 | K15: 314.28 | L15: 118.19712 | M15: 34.93982 | N15: 412.33508 | O15: 1.5386752 | P15: 0.93939592 | Q15: 1.2231738 | R15: 14.429314 | S15: 12.579478 | T15: 767.34815 | U15: 71.571852 | V15: 14.600147 | W15: 6.061447
A16: 67 | B16: 28.36793 | C16: 314.01 | D16: 127.42917 | E16: 40.576196 | F16: 498.91096 | G16: 41.31 | H16: 117.80191 | I16: 4.5619446 | J16: 56.205945 | K16: 272.7 | L16: 128.82482 | M16: 36.014251 | N16: 442.70502 | O16: 1.5294071 | P16: 0.88330442 | Q16: 1.1977609 | R16: 13.843579 | S16: 12.745135 | T16: 853.92404 | U16: 69.179587 | V16: 13.155632 | W16: 6.5071694
A17: 73 | B17: 29.672443 | C17: 272.61 | D17: 138.00127 | E17: 41.314077 | F17: 525.76649 | G17: 32.67 | H17: 128.80904 | I17: 4.3135214 | J17: 55.130754 | K17: 239.94 | L17: 139.20593 | M17: 37.000556 | N17: 470.63574 | O17: 1.5242093 | P17: 0.83687676 | Q17: 1.1719151 | R17: 13.339932 | S17: 12.835418 | T17: 936.98551 | U17: 66.964626 | V17: 11.984153 | W17: 6.9371863
A18: 79 | B18: 30.861677 | C18: 239.94 | D18: 148.35118 | E18: 42.021817 | F18: 550.67533 | G18: 26.73 | H18: 138.65219 | I18: 4.0892394 | J18: 53.852074 | K18: 213.21 | L18: 149.52277 | M18: 37.932577 | N18: 496.82326 | O18: 1.5241464 | P18: 0.79697281 | Q18: 1.1464692 | R18: 12.898079 | S18: 12.873735 | T18: 1017.0251 | U18: 64.842847 | V18: 11.140285 | W18: 7.359205
A19: 85 | B19: 31.963552 | C19: 213.21 | D19: 158.66764 | E19: 42.714414 | F19: 574.21173 | G19: 22.14 | H19: 148.60013 | I19: 3.8905065 | J19: 52.564136 | K19: 191.07 | L19: 159.7932 | M19: 38.823908 | N19: 521.6476 | O19: 1.5270298 | P19: 0.76329786 | Q19: 1.1217988 | R19: 12.525806 | S19: 12.875454 | T19: 1094.4136 | U19: 62.841508 | V19: 10.384128 | W19: 7.7738907
A20: 91 | B20: 32.997683 | C20: 191.07 | D20: 168.95538 | E20: 43.403695 | F20: 596.80243 | G20: 191.07 | H20: 168.95538 | I20: 43.403695 | J20: 596.80243 | K20: - | L20: - | M20: - | N20: - | O20: - | P20: - | Q20: 1.0981614 | R20: - | S20: 12.8524 | T20: 1169.5684 | U20: 61.3566 | V20: - | W20: -
A22: Distribution des volumes produits par classe de grosseur
A23: Age | B23: Hdom | C23: Classes de grosseur - Volume sur pied | K23: VMV | M23: Classes de grosseur - Volume prélevés | U23: VMP | W23: VMA totale
C24: 20-40 | D24: 40-60 | E24: 60-70 | F24: 70-90 | G24: 90-120 | H24: 120-150 | I24: 150-180 | J24: 180+ | K24: VMV | L24: VMA | M24: 20-40 | N24: 40-60 | O24: 60-70 | P24: 70-90 | Q24: 90-120 | R24: 120-150 | S24: 150-180 | T24: 180+ | U24: VMP | V24: VMA
A25: années | B25: m | C25: m³/ha | D25: m³/ha | E25: m³/ha | F25: m³/ha | G25: m³/ha | H25: m³/ha | I25: m³/ha | J25: m³/ha | K25: € /ha | L25: € /ha | M25: m³/ha | N25: m³/ha | O25: m³/ha | P25: m³/ha | Q25: m³/ha | R25: m³/ha | S25: m³/ha | T25: m³/ha | U25: € /ha | V25: € /ha | W25: € /ha
A26: 25 | B26: 13.421578 | C26: 33.566812 | D26: 110.5093 | E26: 25.771256 | F26: 0 | G26: 0 | H26: 0 | I26: 0 | J26: 0 | K26: 5144.3187 | L26: 3135.621 | M26: 13.041748 | N26: 26.971217 | O26: 6.7493724 | P26: 0 | Q26: 0 | R26: 0 | S26: 0 | T26: 0 | U26: 967.22108 | V26: 589.55111 | W26: 3135.621
A27: 31 | B27: 16.383631 | C27: 7.3030689 | D27: 104.05032 | E27: 66.420928 | F27: 46.736131 | G27: 0 | H27: 0 | I27: 0 | J27: 0 | K27: 8677.9461 | L27: 4696.9033 | M27: 5.4321966 | N27: 22.058769 | O27: 5.7399737 | P27: 4.1722745 | Q27: 0 | R27: 0 | S27: 0 | T27: 0 | U27: 935.452 | V27: 506.30963 | W27: 5286.4544
A28: 37 | B28: 19.053064 | C28: 0.44244687 | D28: 45.690377 | E28: 84.045424 | F28: 143.98457 | G28: 17.312935 | H28: 0 | I28: 0 | J28: 0 | K28: 13610.507 | L28: 6541.3582 | M28: 0.44244687 | N28: 21.305423 | O28: 9.011362 | P28: 10.070371 | Q28: 0.94285864 | R28: 0 | S28: 0 | T28: 0 | U28: 1398.0571 | V28: 671.92152 | W28: 7637.219
A29: 43 | B29: 21.415873 | C29: 0 | D29: 6.7608248 | E29: 40.495867 | F29: 204.30775 | G29: 101.8686 | H29: 0 | I29: 0 | J29: 0 | K29: 18958.517 | L29: 8090.9028 | M29: 0 | N29: 5.2045882 | O29: 18.499236 | P29: 19.916518 | Q29: 6.7277195 | R29: 0 | S29: 0 | T29: 0 | U29: 2111.1067 | V29: 900.95435 | W29: 9858.6851
A30: 49 | B30: 23.48685 | C30: 0 | D30: 0 | E30: 5.2795496 | F30: 153.81754 | G30: 244.32847 | H30: 0 | I30: 0 | J30: 0 | K30: 24058.664 | L30: 9117.2337 | M30: 0 | N30: 0 | O30: 4.6577912 | P30: 41.271354 | Q30: 14.44727 | R30: 0 | S30: 0 | T30: 0 | U30: 2979.487 | V30: 1129.1018 | W30: 11785.97
A31: 55 | B31: 25.305497 | C31: 0 | D31: 0 | E31: 0 | F31: 37.706294 | G31: 350.48025 | H31: 50.248893 | I31: 0 | J31: 0 | K31: 28413.062 | L31: 9561.1161 | M31: 0 | N31: 0 | O31: 0 | P31: 21.398319 | Q31: 35.350192 | R31: 2.1981286 | S31: 0 | T31: 0 | U31: 3272.2049 | V31: 1101.1109 | W31: 13358.954
A32: 61 | B32: 26.927701 | C32: 0 | D32: 0 | E32: 0 | F32: 0.8249415 | G32: 307.01616 | H32: 162.1379 | I32: 0 | J32: 0 | K32: 32443.993 | L32: 9694.4645 | M32: 0 | N32: 0 | O32: 0 | P32: 0.68848253 | Q32: 49.525525 | R32: 7.4299157 | S32: 0 | T32: 0 | U32: 3518.3516 | V32: 1051.3051 | W32: 14593.414
A33: 67 | B33: 28.36793 | C33: 0 | D33: 0 | E33: 0 | F33: 0 | G33: 163.88036 | H33: 334.76066 | I33: 0 | J33: 0 | K33: 36056.097 | L33: 9566.8111 | M33: 0 | N33: 0 | O33: 0 | P33: 0 | Q33: 41.156601 | R33: 14.779397 | S33: 0 | T33: 0 | U33: 3631.6524 | V33: 963.59106 | W33: 15517.065
A34: 73 | B34: 29.672443 | C34: 0 | D34: 0 | E34: 0 | F34: 0 | G34: 22.877168 | H34: 435.52391 | I34: 67.067773 | J34: 0 | K34: 39280.948 | L34: 9254.8507 | M34: 0 | N34: 0 | O34: 0 | P34: 0 | Q34: 12.651675 | R34: 39.454682 | S34: 2.726753 | T34: 0 | U34: 3721.7697 | V34: 876.87352 | W34: 16168.696
A35: 79 | B35: 30.861677 | C35: 0 | D35: 0 | E35: 0 | F35: 0 | G35: 0.13956472 | H35: 353.73754 | I35: 196.53734 | J35: 0 | K35: 42058.787 | L35: 8799.1998 | M35: 0 | N35: 0 | O35: 0 | P35: 0 | Q35: 0.13956472 | R35: 46.220094 | S35: 7.2315291 | T35: 0 | U35: 3734.3467 | V35: 781.26986 | W35: 16589.919
A36: 85 | B36: 31.963552 | C36: 0 | D36: 0 | E36: 0 | F36: 0 | G36: 0 | H36: 184.705 | I36: 389.29957 | J36: 0 | K36: 44402.771 | L36: 8248.8894 | M36: 0 | N36: 0 | O36: 0 | P36: 0 | Q36: 0 | R36: 41.719977 | S36: 10.637002 | T36: 0 | U36: 3702.9719 | V36: 687.91665 | W36: 16820.878
A37: 91 | B37: 32.997683 | C37: 0 | D37: 0 | E37: 0 | F37: 0 | G37: 0 | H37: 18.223482 | I37: 508.5928 | J37: 69.986155 | K37: 46320.09 | L37: 7641.0627 | M37: 0 | N37: 0 | O37: 0 | P37: 0 | Q37: 0 | R37: 18.223482 | S37: 508.5928 | T37: 69.986155 | U37: 46320.09 | V37: 7641.0627 | W37: 16900.968
A38: Total | B38: - | C38: - | D38: - | E38: - | F38: - | G38: - | H38: - | I38: - | J38: - | K38: - | L38: - | M38: 18.916391 | N38: 75.539998 | O38: 44.657735 | P38: 97.517319 | Q38: 160.94141 | R38: 170.02568 | S38: 529.18808 | T38: 69.986155 | U38: - | V38: 16900.968 | W38: -
W40: J. Perin, 2016
W41: (j.perin@ulg.ac.be)

Sheet Ep4A
D1: Classe de productivité 4, plantation 2.5 x 2 m
A3: Caractéristiques : | E3: Essence : épicéa commun | K3: Plantation : 2.5 x 2 (90% de reprise) | R3: Rotation : 6 ans
E4: Classe IV (21 m à 50 ans) | K4: Cloisonnement : 1 ligne sur 9 | R4: Taux d'actualisation : 2 %
A5: Table de production
A6: Age | B6: Hdom | C6: Avant prélèvement | G6: Prélèvement | K6: Après prélèvement | O6: Accroissements | U6: h/d | V6: Ecl | W6: Dist
C7: Nha | D7: Cg | E7: Gha | F7: Vha | G7: Nha | H7: Cg | I7: Gha | J7: Vha | K7: Nha | L7: Cg | M7: Gha | N7: Vha | O7: ACC | P7: ACG | Q7: AMG | R7: ACV | S7: AMV | T7: PTV
A8: années | B8: m | C8: N/ha | D8: cm | E8: m²/ha | F8: m³/ha | G8: N/ha | H8: cm | I8: m²/ha | J8: m³/ha | K8: N/ha | L8: cm | M8: m²/ha | N8: m³/ha | O8: cm/ha/an | P8: m²/ha/an | Q8: m²/ha/an | R8: m³/ha/an | S8: m³/ha/an | T8: m³/ha | V8: % | W8: m
A9: 29 | B9: 13.339913 | C9: 1707.435 | D9: 45.51009 | E9: 28.14166 | F9: 169.94287 | G9: 557.415 | H9: 42.567365 | I9: 8.0375246 | J9: 47.152496 | K9: 1150.02 | L9: 46.869998 | M9: 20.104135 | N9: 122.79038 | O9: 1.5001472 | P9: 1.4034191 | Q9: 0.97040206 | R9: 14.155882 | S9: 5.860099 | T9: 169.94287 | U9: 89.414496 | V9: 32.646338 | W9: 3.1687063
A10: 35 | B10: 15.786137 | C10: 1148.31 | D10: 55.870881 | E10: 28.52465 | F10: 207.72567 | G10: 250.11 | H10: 46.004756 | I10: 4.2123715 | J10: 28.38191 | K10: 898.2 | L10: 58.321842 | M10: 24.312278 | N10: 179.34376 | O10: 1.4467302 | P10: 1.2868312 | Q10: 1.0446336 | R10: 14.611805 | S10: 7.2822332 | T10: 254.87816 | U10: 85.034369 | V10: 21.780704 | W10: 3.5854871
A11: 41 | B11: 17.996597 | C11: 896.67 | D11: 67.002224 | E11: 32.033265 | F11: 267.01459 | G11: 160.65 | H11: 56.891802 | I11: 4.1378071 | J11: 33.015149 | K11: 736.02 | L11: 69.012359 | M11: 27.895458 | N11: 233.99944 | O11: 1.3978031 | P11: 1.1858025 | Q11: 1.0800771 | R11: 14.627987 | S11: 8.3548535 | T11: 342.54899 | U11: 81.924422 | V11: 17.91629 | W11: 3.9608635
A12: 47 | B12: 19.965145 | C12: 734.4 | D12: 77.399178 | E12: 35.010273 | F12: 321.76736 | G12: 127.08 | H12: 67.642535 | I12: 4.6270809 | J12: 41.561313 | K12: 607.32 | L12: 79.288982 | M12: 30.383192 | N12: 280.20604 | O12: 1.3708603 | P12: 1.0923102 | Q12: 1.093574 | R12: 14.275707 | S12: 9.155679 | T12: 430.31691 | U12: 79.106013 | V12: 17.303922 | W12: 4.3603956
A13: 53 | B13: 21.706965 | C13: 606.06 | D13: 87.514144 | E13: 36.937054 | F13: 365.86028 | G13: 109.53 | H13: 77.425876 | I13: 5.2251104 | J13: 51.00778 | K13: 496.53 | L13: 89.586715 | M13: 31.711943 | N13: 314.8525 | O13: 1.3684553 | P13: 1.0029343 | Q13: 1.0934309 | R13: 13.655031 | S13: 9.7353048 | T13: 515.97115 | U13: 76.121155 | V13: 18.072468 | W13: 4.8223856
A14: 59 | B14: 23.262908 | C14: 495.72 | D14: 97.797447 | E14: 37.729549 | F14: 396.78269 | G14: 78.12 | H14: 88.13092 | I14: 4.8284638 | J14: 50.377112 | K14: 417.6 | L14: 99.501539 | M14: 32.901085 | N14: 346.40558 | O14: 1.3641525 | P14: 0.92955383 | Q14: 1.0842279 | R14: 13.072004 | S14: 10.133921 | T14: 597.90134 | U14: 73.448693 | V14: 15.758896 | W14: 5.2584099
A15: 65 | B15: 24.668624 | C15: 416.97 | D15: 107.68645 | E15: 38.478408 | F15: 424.8376 | G15: 59.22 | H15: 97.472388 | I15: 4.4773573 | J15: 49.179061 | K15: 357.75 | L15: 109.28518 | M15: 34.001051 | N15: 375.65854 | O15: 1.3590304 | P15: 0.87061254 | Q15: 1.0699503 | R15: 12.567676 | S15: 10.405129 | T15: 676.33336 | U15: 70.914249 | V15: 14.202461 | W15: 5.6812626
A16: 71 | B16: 25.951462 | C16: 357.39 | D16: 117.43936 | E16: 39.224726 | F16: 451.0646 | G16: 45.72 | H16: 107.65818 | I16: 4.2168724 | J16: 48.449398 | K16: 311.67 | L16: 118.80649 | M16: 35.007854 | N16: 402.6152 | O16: 1.3559726 | P16: 0.82262373 | Q16: 1.0531048 | R16: 12.1368 | S16: 10.587879 | T16: 751.73942 | U16: 68.623289 | V16: 12.792747 | W16: 6.0867741
A17: 77 | B17: 27.125673 | C17: 311.49 | D17: 126.94233 | E17: 39.943596 | F17: 475.436 | G17: 36.54 | H17: 117.26122 | I17: 3.9982273 | J17: 47.661237 | K17: 274.95 | L17: 128.17388 | M17: 35.945369 | N17: 427.77476 | O17: 1.3541846 | P17: 0.78361525 | Q17: 1.0351452 | R17: 11.780669 | S17: 10.708574 | T17: 824.56022 | U17: 66.486098 | V17: 11.730714 | W17: 6.4804897
A18: 83 | B18: 28.214954 | C18: 274.95 | D18: 136.29899 | E18: 40.64706 | F18: 498.45878 | G18: 29.79 | H18: 126.92789 | I18: 3.8192205 | J18: 47.016933 | K18: 245.16 | L18: 137.39415 | M18: 36.82784 | N18: 451.44184 | O18: 1.3564506 | P18: 0.74871776 | Q18: 1.0169624 | R18: 11.454009 | S18: 10.786075 | T18: 895.24423 | U18: 64.515039 | V18: 10.834697 | W18: 6.8629349
A19: 89 | B19: 29.233454 | C19: 245.16 | D19: 145.53286 | E19: 41.320146 | F19: 520.1659 | G19: 24.75 | H19: 136.23352 | I19: 3.6553862 | J19: 46.218375 | K19: 220.41 | L19: 146.54024 | M19: 37.66476 | N19: 473.94752 | O19: 1.3605 | P19: 0.71884893 | Q19: 0.99887845 | R19: 11.17705 | S19: 10.831104 | T19: 963.96829 | U19: 62.671937 | V19: 10.095448 | W19: 7.2380076
A20: 95 | B20: 30.200857 | C20: 220.41 | D20: 154.70324 | E20: 41.977854 | F20: 541.00982 | G20: 220.41 | H20: 154.70324 | I20: 41.977854 | J20: 541.00982 | K20: - | L20: - | M20: - | N20: - | O20: - | P20: - | Q20: 0.98119238 | R20: - | S20: 10.852954 | T20: 1031.0306 | U20: 61.329544 | V20: - | W20: -
A22: Distribution des volumes produits par classe de grosseur
A23: Age | B23: Hdom | C23: Classes de grosseur - Volume sur pied | K23: VMV | M23: Classes de grosseur - Volume prélevés | U23: VMP | W23: VMA totale
C24: 20-40 | D24: 40-60 | E24: 60-70 | F24: 70-90 | G24: 90-120 | H24: 120-150 | I24: 150-180 | J24: 180+ | K24: VMV | L24: VMA | M24: 20-40 | N24: 40-60 | O24: 60-70 | P24: 70-90 | Q24: 90-120 | R24: 120-150 | S24: 150-180 | T24: 180+ | U24: VMP | V24: VMA
A25: années | B25: m | C25: m³/ha | D25: m³/ha | E25: m³/ha | F25: m³/ha | G25: m³/ha | H25: m³/ha | I25: m³/ha | J25: m³/ha | K25: € /ha | L25: € /ha | M25: m³/ha | N25: m³/ha | O25: m³/ha | P25: m³/ha | Q25: m³/ha | R25: m³/ha | S25: m³/ha | T25: m³/ha | U25: € /ha | V25: € /ha | W25: € /ha
A26: 29 | B26: 13.339913 | C26: 32.687713 | D26: 111.07676 | E26: 25.880015 | F26: 0 | G26: 0 | H26: 0 | I26: 0 | J26: 0 | K26: 5144.6486 | L26: 2897.0149 | M26: 12.502156 | N26: 28.034747 | O26: 6.3172104 | P26: 0 | Q26: 0 | R26: 0 | S26: 0 | T26: 0 | U26: 968.91028 | V26: 545.6053 | W26: 2897.0149
A27: 35 | B27: 15.786137 | C27: 8.3339586 | D27: 103.61367 | E27: 58.981156 | F27: 36.65221 | G27: 0 | H27: 0 | I27: 0 | J27: 0 | K27: 7822.4192 | L27: 3911.4256 | M27: 5.4051164 | N27: 16.40866 | O27: 3.5566147 | P27: 2.8668471 | Q27: 0 | R27: 0 | S27: 0 | T27: 0 | U27: 663.91782 | V27: 331.97724 | W27: 4457.0309
A28: 41 | B28: 17.996597 | C28: 0.89591684 | D28: 59.977163 | E28: 83.275396 | F28: 118.13559 | G28: 4.5820142 | H28: 0 | I28: 0 | J28: 0 | K28: 11936.501 | L28: 5299.9285 | M28: 0.7987672 | N28: 19.130035 | O28: 5.2622196 | P28: 7.4042317 | Q28: 0.27139276 | R28: 0 | S28: 0 | T28: 0 | U28: 1035.1319 | V28: 459.60914 | W28: 6177.511
A29: 47 | B29: 19.965145 | C29: 0 | D29: 15.574151 | E29: 64.073044 | F29: 183.2385 | G29: 58.637951 | H29: 0 | I29: 0 | J29: 0 | K29: 16368.935 | L29: 6453.7532 | M29: 0 | N29: 9.682299 | O29: 16.218261 | P29: 11.066024 | Q29: 4.3510194 | R29: 0 | S29: 0 | T29: 0 | U29: 1615.8528 | V29: 637.07965 | W29: 7790.9449
A30: 53 | B30: 21.706965 | C30: 0 | D30: 1.1897578 | E30: 16.287211 | F30: 194.97536 | G30: 153.15528 | H30: 0 | I30: 0 | J30: 0 | K30: 20626.609 | L30: 7221.3556 | M30: 0 | N30: 1.1417424 | O30: 10.443542 | P30: 30.594338 | Q30: 8.5754866 | R30: 0 | S30: 0 | T30: 0 | U30: 2300.0482 | V30: 805.24463 | W30: 9195.627
A31: 59 | B31: 23.262908 | C31: 0 | D31: 0 | E31: 0.68073231 | F31: 108.43495 | G31: 285.3747 | H31: 2.0883219 | I31: 0 | J31: 0 | K31: 24367.085 | L31: 7575.1884 | M31: 0 | N31: 0 | O31: 0.5726811 | P31: 34.290703 | Q31: 15.309737 | R31: 0 | S31: 0 | T31: 0 | U31: 2594.9211 | V31: 806.70366 | W31: 10354.704
A32: 65 | B32: 24.668624 | C32: 0 | D32: 0 | E32: 0 | F32: 19.247063 | G32: 342.83184 | H32: 62.607723 | I32: 0 | J32: 0 | K32: 27902.617 | L32: 7702.5367 | M32: 0 | N32: 0 | O32: 0 | P32: 11.650395 | Q32: 35.829505 | R32: 1.5481824 | S32: 0 | T32: 0 | U32: 2775.3476 | V32: 766.13662 | W32: 11288.756
A33: 71 | B33: 25.951462 | C33: 0 | D33: 0 | E33: 0 | F33: 0.13709442 | G33: 288.8419 | H33: 161.88895 | I33: 0 | J33: 0 | K33: 31241.626 | L33: 7658.1071 | M33: 0 | N33: 0 | O33: 0 | P33: 0.13709442 | Q33: 42.587172 | R33: 5.5284853 | S33: 0 | T33: 0 | U33: 2955.248 | V33: 724.40549 | W33: 12010.463
A34: 77 | B34: 27.125673 | C34: 0 | D34: 0 | E34: 0 | F34: 0 | G34: 165.91207 | H34: 309.3201 | I34: 0 | J34: 0 | K34: 34301.638 | L34: 7466.2346 | M34: 0 | N34: 0 | O34: 0 | P34: 0 | Q34: 36.82022 | R34: 10.637192 | S34: 0 | T34: 0 | U34: 3073.5517 | V34: 669.00181 | W34: 12542.996
A35: 83 | B35: 28.214954 | C35: 0 | D35: 0 | E35: 0 | F35: 0 | G35: 31.896533 | H35: 424.33961 | I35: 41.982283 | J35: 0 | K35: 37077.884 | L35: 7166.3941 | M35: 0 | N35: 0 | O35: 0 | P35: 0 | Q35: 15.651988 | R35: 29.390116 | S35: 1.7344755 | T35: 0 | U35: 3155.8756 | V35: 609.96598 | W35: 12912.158
A36: 89 | B36: 29.233454 | C36: 0 | D36: 0 | E36: 0 | F36: 0 | G36: 0.26866415 | H36: 371.99648 | I36: 147.69389 | J36: 0 | K36: 39542.4 | L36: 6786.5295 | M36: 0 | N36: 0 | O36: 0 | P36: 0 | Q36: 0.26866415 | R36: 41.567478 | S36: 4.1753658 | T36: 0 | U36: 3190.2485 | V36: 547.53165 | W36: 13142.259
A37: 95 | B37: 30.200857 | C37: 0 | D37: 0 | E37: 0 | F37: 0 | G37: 0 | H37: 246.90623 | I37: 294.10359 | J37: 0 | K37: 41710.341 | L37: 6356.6372 | M37: 0 | N37: 0 | O37: 0 | P37: 0 | Q37: 0 | R37: 246.90623 | S37: 294.10359 | T37: 0 | U37: 41710.341 | V37: 6356.6372 | W37: 13259.898
A38: Total | B38: - | C38: - | D38: - | E38: - | F38: - | G38: - | H38: - | I38: - | J38: - | K38: - | L38: - | M38: 18.706039 | N38: 74.397483 | O38: 42.37053 | P38: 98.009632 | Q38: 159.66518 | R38: 335.57769 | S38: 300.01343 | T38: 0 | U38: - | V38: 13259.898 | W38: -
W40: J. Perin, 2016
W41: (j.perin@ulg.ac.be)

Sheet Ep0B
D1: Classe de productivité 0, plantation 2 x 2 m
A3: Caractéristiques : | E3: Essence : épicéa commun | K3: Plantation : 2 x 2 (90% de reprise) | R3: Rotation : 6 ans
E4: Classe 0 (33 m à 50 ans) | K4: Cloisonnement: 1 ligne sur 11 | R4: Taux d'actualisation : 2 %
A5: Table de production
A6: Age | B6: Hdom | C6: Avant prélèvement | G6: Prélèvement | K6: Après prélèvement | O6: Accroissements | U6: h/d | V6: Ecl | W6: Dist
C7: Nha | D7: Cg | E7: Gha | F7: Vha | G7: Nha | H7: Cg | I7: Gha | J7: Vha | K7: Nha | L7: Cg | M7: Gha | N7: Vha | O7: ACC | P7: ACG | Q7: AMG | R7: ACV | S7: AMV | T7: PTV
A8: années | B8: m | C8: N/ha | D8: cm | E8: m²/ha | F8: m³/ha | G8: N/ha | H8: cm | I8: m²/ha | J8: m³/ha | K8: N/ha | L8: cm | M8: m²/ha | N8: m³/ha | O8: cm/ha/an | P8: m²/ha/an | Q8: m²/ha/an | R8: m³/ha/an | S8: m³/ha/an | T8: m³/ha | V8: % | W8: m
A9: 17 | B9: 12.925321 | C9: 2133.7 | D9: 41.177895 | E9: 28.79067 | F9: 161.55799 | G9: 848.14 | H9: 36.916967 | I9: 9.1983453 | J9: 48.219311 | K9: 1285.56 | L9: 43.762461 | M9: 19.592325 | N9: 113.33868 | O9: 2.3228028 | P9: 2.3827846 | Q9: 1.6935688 | R9: 25.54216 | S9: 9.5034112 | T9: 161.55799 | U9: 92.787502 | V9: 39.749731 | W9: 2.9970122
A10: 23 | B10: 17.556837 | C10: 1279.17 | D10: 57.699278 | E10: 33.889032 | F10: 266.59164 | G10: 447.75 | H10: 49.017509 | I10: 8.5610731 | J10: 63.477943 | K10: 831.42 | L10: 61.872091 | M10: 25.327959 | N10: 203.1137 | O10: 2.2684462 | P10: 2.0315742 | Q10: 1.8733642 | R10: 26.727641 | S10: 13.687433 | T10: 314.81095 | U10: 89.145897 | V10: 35.003166 | W10: 3.7267001
A11: 29 | B11: 21.768702 | C11: 827.46 | D11: 75.482768 | E11: 37.517404 | F11: 363.47954 | G11: 239.22 | H11: 65.896095 | I11: 8.2662205 | J11: 78.064052 | K11: 588.24 | L11: 79.049546 | M11: 29.251184 | N11: 285.41549 | O11: 2.2137234 | P11: 1.7515316 | Q11: 1.9060973 | R11: 26.177643 | S11: 16.385407 | T11: 475.17679 | U11: 86.513332 | V11: 28.910159 | W11: 4.4305476
A12: 35 | B12: 25.467121 | C12: 586.08 | D12: 92.331886 | E12: 39.760373 | F12: 442.48135 | G12: 136.98 | H12: 82.178178 | I12: 7.3613983 | J12: 80.976564 | K12: 449.1 | L12: 95.213612 | M12: 32.398975 | N12: 361.50478 | O12: 2.1485774 | P12: 1.5388907 | Q12: 1.8796003 | R12: 25.050135 | S12: 18.064076 | T12: 632.24265 | U12: 84.029289 | V12: 23.372236 | W12: 5.0706444
A13: 41 | B13: 28.675886 | C13: 447.66 | D13: 108.10508 | E13: 41.632319 | F13: 511.80559 | G13: 97.47 | H13: 98.183961 | I13: 7.4772551 | J13: 91.645216 | K13: 350.19 | L13: 110.70841 | M13: 34.155064 | N13: 420.16038 | O13: 2.114443 | P13: 1.3630662 | Q13: 1.8297404 | R13: 23.429597 | S13: 19.086426 | T13: 782.54346 | U13: 81.374082 | V13: 21.773221 | W13: 5.7422595
A14: 47 | B14: 31.42659 | C14: 349.38 | D14: 123.39507 | E14: 42.333461 | F14: 560.73796 | G14: 64.8 | H14: 113.50404 | I14: 6.6433599 | J14: 88.102769 | K14: 284.58 | L14: 125.53841 | M14: 35.690101 | N14: 472.63519 | O14: 2.0764122 | P14: 1.2301232 | Q14: 1.770165 | R14: 21.945218 | S14: 19.640873 | T14: 923.12104 | U14: 78.644888 | V14: 18.547141 | W14: 6.3698983
A15: 53 | B15: 33.792086 | C15: 284.22 | D15: 137.99689 | E15: 43.070841 | F15: 604.3065 | G15: 46.35 | H15: 127.57349 | I15: 6.0028947 | J15: 84.558068 | K15: 237.87 | L15: 139.93758 | M15: 37.067946 | N15: 519.74843 | O15: 2.0462832 | P15: 1.1261019 | Q15: 1.7090282 | R15: 20.615831 | S15: 19.901743 | T15: 1054.7924 | U15: 75.863089 | V15: 16.30779 | W15: 6.9673054
A16: 59 | B16: 35.832015 | C16: 237.69 | D16: 152.21528 | E16: 43.824557 | F16: 643.44342 | G16: 34.65 | H16: 141.2105 | I16: 5.4982865 | J16: 81.016085 | K16: 203.04 | L16: 154.01478 | M16: 38.326271 | N16: 562.42733 | O16: 2.0227791 | P16: 1.0463952 | Q16: 1.6497475 | R16: 19.506326 | S16: 19.974362 | T16: 1178.4873 | U16: 73.090123 | V16: 14.577811 | W16: 7.5412594
A17: 65 | B17: 37.622863 | C17: 203.04 | D17: 166.15146 | E17: 44.604642 | F17: 679.46529 | G17: 26.55 | H17: 155.813 | I17: 5.1293462 | J17: 78.664576 | K17: 176.49 | L17: 167.65155 | M17: 39.475296 | N17: 600.80071 | O17: 2.0085604 | P17: 0.97986901 | Q17: 1.5940535 | R17: 18.51204 | S17: 19.931158 | T17: 1295.5253 | U17: 70.500816 | V17: 13.076241 | W17: 8.0886237
