Workbook

Sheet Synthèse
F2: Accord-Cadre IV (2014 -2019)
F3: de Recherche et de Vulgarisation forestières
B5: Nouvelles normes sylvicoles pour les peuplements purs équiennes de douglas
B7: 1. Evolution de la hauteur dominante selon les 5 classes de productivité
B9: Age | C9: Classe de productivité
C10: IV | D10: III | E10: II | F10: I | G10: 0
B11: 20 | C11: 11.7 | D11: 13.8 | E11: 15.9 | F11: 17.9 | G11: 20
B12: 25 | C12: 14.7 | D12: 17.2 | E12: 19.7 | F12: 22.2 | G12: 24.7
B13: 30 | C13: 17.6 | D13: 20.4 | E13: 23.3 | F13: 26.2 | G13: 29.1
B14: 35 | C14: 20.3 | D14: 23.6 | E14: 26.8 | F14: 30 | G14: 33.2
B15: 40 | C15: 23 | D15: 26.5 | E15: 30 | F15: 33.6 | G15: 37.1
B16: 45 | C16: 25.6 | D16: 29.3 | E16: 33.1 | F16: 36.9 | G16: 40.7
B17: 50 | C17: 28 | D17: 32 | E17: 36 | F17: 40 | G17: 44
B18: 55 | C18: 30.3 | D18: 34.5 | E18: 38.7 | F18: 42.9 | G18: 47.1
B19: 60 | C19: 32.5 | D19: 36.9 | E19: 41.2 | F19: 45.6 | G19: 50
B20: 65 | C20: 34.6 | D20: 39.1 | E20: 43.6 | F20: 48.1 | G20: -
B21: 70 | C21: 36.6 | D21: 41.3 | E21: 45.9 | F21: 50.5 | G21: -
B22: 75 | C22: 38.5 | D22: 43.3 | E22: 48 | F22: - | G22: -
B23: 80 | C23: 40.4 | D23: 45.2 | E23: 50 | F23: - | G23: -
B24: 85 | C24: 42.1 | D24: 47 | E24: - | F24: - | G24: -
B25: 90 | C25: 43.8 | D25: 48.8 | E25: - | F25: - | G25: -
B26: 95 | C26: 45.5 | D26: 50.5 | E26: - | F26: - | G26: -
B27: 100 | C27: 47.1 | D27: - | E27: - | F27: - | G27: -
B29: 2. Synthèse des nouvelles normes
C31: 2.1. Ecartement à la plantation : 2.5 x 2 m
B33: Productivité | D33: 1ère éclaircie | F33: Caractéristique de la coupe rase | K33: Accroissement et stabilité | O33: Recettes
B34: Classe | C34: H50 | D34: Age | E34: Ecl | F34: Age cible | G34: Hdom | H34: Cg | I34: Nha | J34: Vha | K34: AMC | L34: PTV | M34: AMV | N34: h/d | O34: VA Ecl | P34: VA Mab | Q34: VA Total
B35: années | C35: m | D35: années | E35: % | F35: années | G35: m | H35: cm | I35: N/ha | J35: m³/ha | K35: cm/an | L35: m³/ha | M35: m³/ha/an | O35: € /ha | P35: € /ha | Q35: € /ha
B36: 0 | C36: 44 | D36: =Do0A!A$9 -> 13 | E36: =Do0A!V$9 -> 32.643103 | F36: =Do0A!A16 -> 55 | G36: =Do0A!B16 -> 46.083975 | H36: =Do0A!D16 -> 206.44805 | I36: =Do0A!C16 -> 141.39 | J36: =Do0A!F16 -> 767.61178 | K36: =H36/F36 -> 3.753601 | L36: =Do0A!T16 -> 1427.0133 | M36: =Do0A!S16 -> 25.945697 | N36: =Do0A!U13 -> 77.079433 | O36: =Q36-P36 -> 15303.771 | P36: =Do0A!L$33 -> 21721.347 | Q36: =Do0A!W$33 -> 37025.118
B37: 1 | C37: 40 | D37: =Do1A!A$9 -> 15 | E37: =Do1A!V$9 -> 32.643232 | F37: =Do1A!A16 -> 57 | G37: =Do1A!B16 -> 43.08956 | H37: =Do1A!D16 -> 191.88746 | I37: =Do1A!C16 -> 158.85 | J37: =Do1A!F16 -> 708.35018 | K37: =H37/F37 -> 3.3664466 | L37: =Do1A!T16 -> 1300.442 | M37: =Do1A!S16 -> 22.814772 | N37: =Do1A!U14 -> 74.383412 | O37: =Q37-P37 -> 12525.876 | P37: =Do1A!L$33 -> 18917.569 | Q37: =Do1A!W$33 -> 31443.444
B38: 2 | C38: 36 | D38: =Do2A!A$9 -> 17 | E38: =Do2A!V$9 -> 32.646457 | F38: =Do2A!A17 -> 65 | G38: =Do2A!B17 -> 42.710928 | H38: =Do2A!D17 -> 196.28922 | I38: =Do2A!C17 -> 150.21 | J38: =Do2A!F17 -> 697.92314 | K38: =H38/F38 -> 3.0198341 | L38: =Do2A!T17 -> 1307.2021 | M38: =Do2A!S17 -> 20.110802 | N38: =Do2A!U15 -> 71.891652 | O38: =Q38-P38 -> 11824.318 | P38: =Do2A!L$34 -> 16025.092 | Q38: =Do2A!W$34 -> 27849.41
B39: 3 | C39: 32 | D39: =Do3A!A$9 -> 19 | E39: =Do3A!V$9 -> 32.646327 | F39: =Do3A!A18 -> 73 | G39: =Do3A!B18 -> 41.618617 | H39: =Do3A!D18 -> 196.47049 | I39: =Do3A!C18 -> 147.96 | J39: =Do3A!F18 -> 676.99329 | K39: =H39/F39 -> 2.6913766 | L39: =Do3A!T18 -> 1277.8318 | M39: =Do3A!S18 -> 17.504545 | N39: =Do3A!U16 -> 69.619039 | O39: =Q39-P39 -> 10495.316 | P39: =Do3A!L$35 -> 13287.758 | Q39: =Do3A!W$35 -> 23783.074
B40: 4 | C40: 28 | D40: =Do4A!A$9 -> 23 | E40: =Do4A!V$9 -> 32.645716 | F40: =Do4A!A19 -> 83 | G40: =Do4A!B19 -> 40.676788 | H40: =Do4A!D19 -> 193.66089 | I40: =Do4A!C19 -> 149.49 | J40: =Do4A!F19 -> 653.94809 | K40: =H40/F40 -> 2.3332637 | L40: =Do4A!T19 -> 1245.8936 | M40: =Do4A!S19 -> 15.010766 | N40: =Do4A!U19 -> 65.219646 | O40: =Q40-P40 -> 8906.7235 | P40: =Do4A!L$36 -> 10476.568 | Q40: =Do4A!W$36 -> 19383.292
C42: 2.2. Ecartement à la plantation : 2 x 2 m
B44: Productivité | D44: 1ère éclaircie | F44: Caractéristique de la coupe rase | K44: Accroissement et stabilité | O44: Recettes
B45: Classe | C45: H50 | D45: Age | E45: Ecl | F45: Age cible | G45: Hdom | H45: Cg | I45: Nha | J45: Vha | K45: AMC | L45: PTV | M45: AMV | N45: h/d | O45: VA Ecl | P45: VA Mab | Q45: VA Total
B46: années | C46: m | D46: années | E46: % | F46: années | G46: m | H46: cm | I46: N/ha | J46: m³/ha | K46: cm/an | L46: m³/ha | M46: m³/ha/an | O46: € /ha | P46: € /ha | Q46: € /ha
B47: 0 | C47: 44 | D47: =Do0B!A$9 -> 13 | E47: =Do0B!V$9 -> 39.7503 | F47: =Do0B!A16 -> 55 | G47: =Do0B!B16 -> 46.024902 | H47: =Do0B!D16 -> 198.03472 | I47: =Do0B!C16 -> 151.38 | J47: =Do0B!F16 -> 753.4934 | K47: =H47/F47 -> 3.6006313 | L47: =Do0B!T16 -> 1413.9121 | M47: =Do0B!S16 -> 25.707492 | N47: =Do0B!U13 -> 80.453781 | O47: =Q47-P47 -> 14639.587 | P47: =Do0B!L$33 -> 21073.806 | Q47: =Do0B!W$33 -> 35713.394
B48: 1 | C48: 40 | D48: =Do1B!A$9 -> 15 | E48: =Do1B!V$9 -> 39.751556 | F48: =Do1B!A16 -> 57 | G48: =Do1B!B16 -> 43.113682 | H48: =Do1B!D16 -> 185.87563 | I48: =Do1B!C16 -> 167.31 | J48: =Do1B!F16 -> 698.71084 | K48: =H48/F48 -> 3.2609759 | L48: =Do1B!T16 -> 1292.5875 | M48: =Do1B!S16 -> 22.676974 | N48: =Do1B!U14 -> 76.865069 | O48: =Q48-P48 -> 11890.564 | P48: =Do1B!L$33 -> 18414.174 | Q48: =Do1B!W$33 -> 30304.737
B49: 2 | C49: 36 | D49: =Do2B!A$9 -> 17 | E49: =Do2B!V$9 -> 39.748317 | F49: =Do2B!A17 -> 65 | G49: =Do2B!B17 -> 42.786904 | H49: =Do2B!D17 -> 189.66954 | I49: =Do2B!C17 -> 158.94 | J49: =Do2B!F17 -> 688.64986 | K49: =H49/F49 -> 2.9179929 | L49: =Do2B!T17 -> 1299.6461 | M49: =Do2B!S17 -> 19.994556 | N49: =Do2B!U15 -> 74.538991 | O49: =Q49-P49 -> 11208.013 | P49: =Do2B!L$34 -> 15617.939 | Q49: =Do2B!W$34 -> 26825.952
...

Sheet Do0A
D1: Classe de productivité 0, plantation 2.5 x 2 m
A3: Caractéristiques : | E3: Essence : douglas | K3: Plantation : 2.5 x 2 (85% de reprise) | R3: Rotation : 6 ans
E4: Classe 0 (44 m à 50 ans) | K4: Cloisonnement : 1 ligne sur 9 | R4: Taux d'actualisation : 2 %
A5: Table de production
A6: Age | B6: Hdom | C6: Avant prélèvement | G6: Prélèvement | K6: Après prélèvement | O6: Accroissements | U6: h/d | V6: Ecl | W6: Dist
C7: Nha | D7: Cg | E7: Gha | F7: Vha | G7: Nha | H7: Cg | I7: Gha | J7: Vha | K7: Nha | L7: Cg | M7: Gha | N7: Vha | O7: ACC | P7: ACG | Q7: AMG | R7: ACV | S7: AMV | T7: PTV
A8: années | B8: m | C8: N/ha | D8: cm | E8: m²/ha | F8: m³/ha | G8: N/ha | H8: cm | I8: m²/ha | J8: m³/ha | K8: N/ha | L8: cm | M8: m²/ha | N8: m³/ha | O8: cm/ha/an | P8: m²/ha/an | Q8: m²/ha/an | R8: m³/ha/an | S8: m³/ha/an | T8: m³/ha | V8: % | W8: m
A9: 13 | B9: 13.158736 | C9: 1613.955 | D9: 44.687253 | E9: 25.647727 | F9: 139.75958 | G9: 526.845 | H9: 43.285319 | I9: 7.8551456 | J9: 42.376026 | K9: 1087.11 | L9: 45.351083 | M9: 17.792581 | N9: 97.383553 | O9: 3.0505319 | P9: 2.8369903 | Q9: 1.9729021 | R9: 28.998151 | S9: 10.750737 | T9: 139.75958 | U9: 91.154139 | V9: 32.643103 | W9: 3.2591019
A10: 19 | B10: 18.923869 | C10: 1079.73 | D10: 63.654274 | E10: 34.814523 | F10: 271.37246 | G10: 411.3 | H10: 55.549037 | I10: 10.099548 | J10: 75.706356 | K10: 668.43 | L10: 68.164312 | M10: 24.714975 | N10: 195.6661 | O10: 3.0559445 | P10: 2.4649724 | Q10: 2.245772 | R10: 31.396964 | S10: 16.513078 | T10: 313.74849 | U10: 87.21732 | V10: 38.092857 | W10: 4.1562984
A11: 25 | B11: 24.428646 | C11: 663.48 | D11: 86.499979 | E11: 39.50481 | F11: 384.04789 | G11: 214.74 | H11: 74.912357 | I11: 9.5898102 | J11: 91.238297 | K11: 448.74 | L11: 91.527593 | M11: 29.915 | N11: 292.80959 | O11: 3.0754292 | P11: 2.1653595 | Q11: 2.2983801 | R11: 32.162645 | S11: 20.085211 | T11: 502.13027 | U11: 83.848872 | V11: 32.365708 | W11: 5.072678
A12: 31 | B12: 29.54923 | C12: 445.77 | D12: 109.98017 | E12: 42.907157 | F12: 485.78546 | G12: 132.84 | H12: 94.851216 | I12: 9.5105319 | J12: 106.09348 | K12: 312.93 | L12: 115.80642 | M12: 33.396625 | N12: 379.69198 | O12: 3.1465998 | P12: 1.9194814 | Q12: 2.2726342 | R12: 31.922959 | S12: 22.422779 | T12: 695.10613 | U12: 80.161054 | V12: 29.800121 | W12: 6.0745077
A13: 37 | B13: 34.27819 | C13: 311.13 | D13: 134.68601 | E13: 44.913514 | F13: 571.22973 | G13: 81.63 | H13: 119.43241 | I13: 9.2658296 | J13: 117.45368 | K13: 229.5 | L13: 139.71056 | M13: 35.647684 | N13: 453.77605 | O13: 3.1972331 | P13: 1.7134498 | Q13: 2.2153662 | R13: 31.024702 | S13: 23.963348 | T13: 886.64389 | U13: 77.079433 | V13: 26.236621 | W13: 7.0932185
A14: 43 | B14: 38.556481 | C14: 228.6 | D14: 158.89396 | E14: 45.928383 | F14: 639.92426 | G14: 51.75 | H14: 141.40052 | I14: 8.2338413 | J14: 114.32768 | K14: 176.85 | L14: 163.65966 | M14: 37.694541 | N14: 525.59658 | O14: 3.2168183 | P14: 1.5452159 | Q14: 2.1453313 | R14: 30.021094 | S14: 24.948654 | T14: 1072.7921 | U14: 74.012596 | V14: 22.637795 | W14: 8.0803868
A15: 49 | B15: 42.495324 | C15: 176.31 | D15: 182.96056 | E15: 46.965837 | F15: 705.72315 | G15: 34.65 | H15: 164.58984 | I15: 7.469636 | J15: 112.20601 | K15: 141.66 | L15: 187.1798 | M15: 39.496201 | N15: 593.51713 | O15: 3.2113759 | P15: 1.4097358 | Q15: 2.0718478 | R15: 29.015774 | S15: 25.569769 | T15: 1252.9187 | U15: 71.323401 | V15: 19.652884 | W15: 9.0284057
A16: 55 | B16: 46.083975 | C16: 141.39 | D16: 206.44805 | E16: 47.954616 | F16: 767.61178 | G16: 24.75 | H16: 185.67681 | I16: 6.7901705 | J16: 108.73843 | K16: 116.64 | L16: 210.59221 | M16: 41.164446 | N16: 658.87335 | O16: 3.1879737 | P16: 1.3029062 | Q16: 1.9996174 | R16: 28.132957 | S16: 25.945697 | T16: 1427.0133 | U16: 68.747593 | V16: 17.504774 | W16: 9.9497216
A17: 61 | B17: 49.371347 | C17: 116.64 | D17: 229.72006 | E17: 48.981883 | F17: 827.67109 | G17: 17.73 | H17: 212.38223 | I17: 6.3640739 | J17: 108.2669 | K17: 98.91 | L17: 232.69143 | M17: 42.617809 | N17: 719.40419 | O17: 3.1664173 | P17: 1.2072186 | Q17: 1.9310885 | R17: 27.159098 | S17: 26.160837 | T17: 1595.8111 | U17: 66.6568 | V17: 15.200617 | W17: 10.804747
A18: 67 | B18: 52.345559 | C18: 98.91 | D18: 251.68994 | E18: 49.861121 | F18: 882.35878 | G18: 13.68 | H18: 232.43347 | I18: 5.8813032 | J18: 104.22776 | K18: 85.23 | L18: 254.64514 | M18: 43.979818 | N18: 778.13102 | O18: 3.1480893 | P18: 1.1277443 | Q18: 1.8662643 | R18: 26.308915 | S18: 26.250233 | T18: 1758.7656 | U18: 64.579446 | V18: 13.830755 | W18: 11.63961
A19: 73 | B19: 55.144435 | C19: 85.23 | D19: 273.53368 | E19: 50.746284 | F19: 935.98451 | G19: 10.53 | H19: 256.32136 | I19: 5.5053901 | J19: 99.700685 | K19: 74.7 | L19: 275.87365 | M19: 45.240894 | N19: 836.28383 | O19: 3.1287406 | P19: 1.0610869 | Q19: 1.805564 | R19: 25.615533 | S19: 26.255057 | T19: 1916.6191 | U19: 62.797354 | V19: 12.354805 | W19: 12.432956
A20: 79 | B20: 57.941541 | C20: 74.7 | D20: 294.64609 | E20: 51.607415 | F20: 989.97702 | G20: 74.7 | H20: 294.64609 | I20: 51.607415 | J20: 989.97702 | K20: - | L20: - | M20: - | N20: - | O20: - | P20: - | Q20: 1.7490215 | R20: - | S20: 26.206485 | T20: 2070.3123 | U20: 61.778767 | V20: - | W20: -
A22: Distribution des volumes produits par classe de grosseur
A23: Age | B23: Hdom | C23: Classes de grosseur - Volume sur pied | K23: VMV | M23: Classes de grosseur - Volume prélevés | U23: VMP | W23: VMA totale
C24: 20-40 | D24: 40-60 | E24: 60-70 | F24: 70-90 | G24: 90-120 | H24: 120-150 | I24: 150-180 | J24: 180+ | K24: VMV | L24: VMA | M24: 20-40 | N24: 40-60 | O24: 60-70 | P24: 70-90 | Q24: 90-120 | R24: 120-150 | S24: 150-180 | T24: 180+ | U24: VMP | V24: VMA
A25: années | B25: m | C25: m³/ha | D25: m³/ha | E25: m³/ha | F25: m³/ha | G25: m³/ha | H25: m³/ha | I25: m³/ha | J25: m³/ha | K25: € /ha | L25: € /ha | M25: m³/ha | N25: m³/ha | O25: m³/ha | P25: m³/ha | Q25: m³/ha | R25: m³/ha | S25: m³/ha | T25: m³/ha | U25: € /ha | V25: € /ha | W25: € /ha
A26: 13 | B26: 13.158736 | C26: 29.558297 | D26: 84.661868 | E26: 22.699003 | F26: 2.4955828 | G26: 0 | H26: 0 | I26: 0 | J26: 0 | K26: 1947.6232 | L26: 1505.5761 | M26: 10.495361 | N26: 23.978839 | O26: 6.7523124 | P26: 0.8046851 | Q26: 0 | R26: 0 | S26: 0 | T26: 0 | U26: 522.32559 | V26: 403.77467 | W26: 1505.5761
A27: 19 | B27: 18.923869 | C27: 6.4573025 | D27: 69.467202 | E27: 59.259943 | F27: 106.05053 | G27: 29.746578 | H27: 0 | I27: 0 | J27: 0 | K27: 8348.0089 | L27: 5730.3301 | M27: 4.7885429 | N27: 33.462429 | O27: 13.838283 | P27: 18.225856 | Q27: 5.0003397 | R27: 0 | S27: 0 | T27: 0 | U27: 1657.839 | V27: 1137.9917 | W27: 6134.1048
A28: 25 | B28: 24.428646 | C28: 0.69518529 | D28: 16.649018 | E28: 28.429456 | F28: 117.02868 | G28: 192.9296 | H28: 27.740215 | I28: 0 | J28: 0 | K28: 17666.079 | L28: 10768.02 | M28: 0.63531399 | N28: 10.720711 | O28: 14.473552 | P28: 33.932778 | Q28: 26.254119 | R28: 4.6460993 | S28: 0 | T28: 0 | U28: 3255.7958 | V28: 1984.508 | W28: 12309.787
A29: 31 | B29: 29.54923 | C29: 0 | D29: 3.4365598 | E29: 6.6980577 | F29: 45.868529 | G29: 209.32102 | H29: 204.20441 | I29: 15.666646 | J29: 0 | K29: 27724.062 | L29: 15005.537 | M29: 0 | N29: 2.8082584 | O29: 5.1621856 | P29: 23.480713 | Q29: 48.867591 | R29: 24.181879 | S29: 1.002621 | T29: 0 | U29: 4872.6818 | V29: 2637.3194 | W29: 18531.811
A30: 37 | B30: 34.27819 | C30: 0 | D30: 0.18667011 | E30: 1.0081328 | F30: 10.619566 | G30: 93.177921 | H30: 268.88663 | I30: 196.31621 | J30: 0 | K30: 38196.884 | L30: 18357.84 | M30: 0 | N30: 0.18667011 | O30: 0.78086025 | P30: 7.7001719 | Q30: 39.700275 | R30: 40.424877 | S30: 27.62622 | T30: 0 | U30: 6553.6569 | V30: 3149.7592 | W30: 24521.434
A31: 43 | B31: 38.556481 | C31: 0 | D31: 0 | E31: 0 | F31: 1.3761228 | G31: 24.061325 | H31: 157.69418 | I31: 302.12022 | J31: 153.8986 | K31: 48104.898 | L31: 20529.667 | M31: 0 | N31: 0 | O31: 0 | P31: 1.2992327 | Q31: 13.896441 | R31: 52.171372 | S31: 33.778944 | T31: 12.407882 | U31: 7165.2214 | V31: 3057.8926 | W31: 29843.02
A32: 49 | B32: 42.495324 | C32: 0 | D32: 0 | E32: 0 | F32: 0 | G32: 3.0027448 | H32: 43.980464 | I32: 233.88788 | J32: 423.98333 | K32: 57213.55 | L32: 21681.558 | M32: 0 | N32: 0 | O32: 0 | P32: 0 | Q32: 2.1409829 | R32: 25.332185 | S32: 51.028618 | T32: 32.835506 | U32: 7738.3828 | V32: 2932.5255 | W32: 34052.803
A33: 55 | B33: 46.083975 | C33: 0 | D33: 0 | E33: 0 | F33: 0 | G33: 0 | H33: 8.0653146 | I33: 80.261111 | J33: 678.44666 | K33: 64549.994 | L33: 21721.347 | M33: 0 | N33: 0 | O33: 0 | P33: 0 | Q33: 0 | R33: 6.8776595 | S33: 34.461982 | T33: 66.560102 | U33: 7983.4062 | V33: 2686.4501 | W33: 37025.118
A34: 61 | B34: 49.371347 | C34: 0 | D34: 0 | E34: 0 | F34: 0 | G34: 0 | H34: 0 | I34: 10.758261 | J34: 815.65503 | K34: 70362.977 | L34: 21024.89 | M34: 0 | N34: 0 | O34: 0 | P34: 0 | Q34: 0 | R34: 0 | S34: 6.717403 | T34: 100.2917 | U34: 8242.8248 | V34: 2463.0067 | W34: 39015.111
A35: 67 | B35: 52.345559 | C35: 0 | D35: 0 | E35: 0 | F35: 0 | G35: 0 | H35: 0 | I35: 0.72489263 | J35: 880.99153 | K35: 75160.344 | L35: 19942.392 | M35: 0 | N35: 0 | O35: 0 | P35: 0 | Q35: 0 | R35: 0 | S35: 0.38497044 | T35: 103.20043 | U35: 8024.9812 | V35: 2129.2787 | W35: 40395.62
A36: 73 | B36: 55.144435 | C36: 0 | D36: 0 | E36: 0 | F36: 0 | G36: 0 | H36: 0 | I36: 0.40528325 | J36: 937.04989 | K36: 79914.71 | L36: 18828.434 | M36: 0 | N36: 0 | O36: 0 | P36: 0 | Q36: 0 | R36: 0 | S36: 0.40528325 | T36: 100.76607 | U36: 7837.7399 | V36: 1846.6233 | W36: 41410.94
A37: 79 | B37: 57.941541 | C37: 0 | D37: 0 | E37: 0 | F37: 0 | G37: 0 | H37: 0 | I37: 0 | J37: 989.97702 | K37: 84395.541 | L37: 17656.553 | M37: 0 | N37: 0 | O37: 0 | P37: 0 | Q37: 0 | R37: 0 | S37: 0 | T37: 989.97702 | U37: 84395.541 | V37: 17656.553 | W37: 42085.683
A38: Total | B38: - | C38: - | D38: - | E38: - | F38: - | G38: - | H38: - | I38: - | J38: - | K38: - | L38: - | M38: 15.919218 | N38: 71.156908 | O38: 41.007194 | P38: 85.443437 | Q38: 135.85975 | R38: 153.63407 | S38: 155.40604 | T38: 1406.0387 | U38: - | V38: 42085.683 | W38: -
W40: J. Perin, 2016
W41: (j.perin@ulg.ac.be)

Sheet Do1A
D1: Classe de productivité 1, plantation 2.5 x 2 m
A3: Caractéristiques : | E3: Essence : douglas | K3: Plantation : 2.5 x 2 (85% de reprise) | R3: Rotation : 6 ans
E4: Classe I (40 m à 50 ans) | K4: Cloisonnement : 1 ligne sur 9 | R4: Taux d'actualisation : 2 %
A5: Table de production
A6: Age | B6: Hdom | C6: Avant prélèvement | G6: Prélèvement | K6: Après prélèvement | O6: Accroissements | U6: h/d | V6: Ecl | W6: Dist
C7: Nha | D7: Cg | E7: Gha | F7: Vha | G7: Nha | H7: Cg | I7: Gha | J7: Vha | K7: Nha | L7: Cg | M7: Gha | N7: Vha | O7: ACC | P7: ACG | Q7: AMG | R7: ACV | S7: AMV | T7: PTV
A8: années | B8: m | C8: N/ha | D8: cm | E8: m²/ha | F8: m³/ha | G8: N/ha | H8: cm | I8: m²/ha | J8: m³/ha | K8: N/ha | L8: cm | M8: m²/ha | N8: m³/ha | O8: cm/ha/an | P8: m²/ha/an | Q8: m²/ha/an | R8: m³/ha/an | S8: m³/ha/an | T8: m³/ha | V8: % | W8: m
A9: 15 | B9: 13.523098 | C9: 1613.29 | D9: 45.696772 | E9: 26.808568 | F9: 150.29545 | G9: 526.63 | H9: 44.222037 | I9: 8.1954578 | J9: 45.497662 | K9: 1086.66 | L9: 46.394614 | M9: 18.61311 | N9: 104.79778 | O9: 2.738253 | P9: 2.5498786 | Q9: 1.7872379 | R9: 26.077198 | S9: 10.019696 | T9: 150.29545 | U9: 91.571111 | V9: 32.643232 | W9: 3.2597766
A10: 21 | B10: 18.672501 | C10: 1079.73 | D10: 62.824132 | E10: 33.912382 | F10: 261.26097 | G10: 391.5 | H10: 54.78718 | I10: 9.3514681 | J10: 69.212088 | K10: 688.23 | L10: 66.966931 | M10: 24.560914 | N10: 192.04889 | O10: 2.7549292 | P10: 2.2327572 | Q10: 2.0051352 | R10: 27.816986 | S10: 14.607554 | T10: 306.75864 | U10: 87.59755 | V10: 36.259065 | W10: 4.0960749
A11: 27 | B11: 23.580745 | C11: 684.18 | D11: 83.496506 | E11: 37.957457 | F11: 358.9508 | G11: 206.01 | H11: 71.75496 | I11: 8.4407745 | J11: 77.891976 | K11: 478.17 | L11: 88.073964 | M11: 29.516683 | N11: 281.05882 | O11: 2.7652905 | P11: 1.9901548 | Q11: 2.0557179 | R11: 28.587249 | S11: 17.542983 | T11: 473.66055 | U11: 84.112367 | V11: 30.110497 | W11: 4.9140947
A12: 33 | B12: 28.157502 | C12: 475.56 | D12: 104.66571 | E12: 41.457612 | F12: 452.58232 | G12: 133.56 | H12: 90.419861 | I12: 8.6894886 | J12: 93.490368 | K12: 342 | L12: 109.72805 | M12: 32.768123 | N12: 359.09195 | O12: 2.831381 | P12: 1.7817298 | Q12: 2.0437973 | R12: 28.432643 | S12: 19.551032 | T12: 645.18405 | U12: 80.616946 | V12: 28.084784 | W12: 5.8106087
A13: 39 | B13: 32.385359 | C13: 340.11 | D13: 126.71634 | E13: 43.458502 | F13: 529.68781 | G13: 87.75 | H13: 110.39724 | I13: 8.5104731 | J13: 102.69423 | K13: 252.36 | L13: 131.91859 | M13: 34.948029 | N13: 426.99358 | O13: 2.8891085 | P13: 1.6020972 | Q13: 2.0034792 | R13: 27.747191 | S13: 20.917433 | T13: 815.77991 | U13: 77.124537 | V13: 25.800476 | W13: 6.7643244
A14: 45 | B14: 36.28041 | C14: 251.37 | D14: 149.25325 | E14: 44.560612 | F14: 593.47673 | G14: 54.27 | H14: 133.81679 | I14: 7.7334129 | J14: 102.92528 | K14: 197.1 | L14: 153.23076 | M14: 36.827199 | N14: 490.55145 | O14: 2.9154714 | P14: 1.453557 | Q14: 1.9499616 | R14: 26.906202 | S14: 21.828068 | T14: 982.26305 | U14: 74.383412 | V14: 21.589689 | W14: 7.6540514
A15: 51 | B15: 39.820658 | C15: 196.38 | D15: 170.72359 | E15: 45.548541 | F15: 651.98866 | G15: 37.26 | H15: 153.82523 | I15: 7.0159764 | J15: 100.38024 | K15: 159.12 | L15: 174.44419 | M15: 38.532565 | N15: 551.60842 | O15: 2.9072118 | P15: 1.3353613 | Q15: 1.8915611 | R15: 26.123627 | S15: 22.425495 | T15: 1143.7003 | U15: 71.713645 | V15: 18.973419 | W15: 8.5186799
A16: 57 | B16: 43.08956 | C16: 158.85 | D16: 191.88746 | E16: 46.544732 | F16: 708.35018 | G16: 26.37 | H16: 175.81718 | I16: 6.4866863 | J16: 99.087635 | K16: 132.48 | L16: 194.92819 | M16: 40.058046 | N16: 609.26255 | O16: 2.8896691 | P16: 1.2351034 | Q16: 1.8330137 | R16: 25.32177 | S16: 22.814772 | T16: 1300.442 | U16: 69.446007 | V16: 16.600567 | W16: 9.3359717
A17: 63 | B17: 46.081128 | C17: 132.39 | D17: 212.26621 | E17: 47.468667 | F17: 761.19317 | G17: 20.25 | H17: 192.19177 | I17: 5.952299 | J17: 95.544879 | K17: 112.14 | L17: 215.69215 | M17: 41.516368 | N17: 665.64829 | O17: 2.8794482 | P17: 1.1528645 | Q17: 1.7760699 | R17: 24.622977 | S17: 23.053534 | T17: 1452.3726 | U17: 67.117944 | V17: 15.295717 | W17: 10.147391
A18: 69 | B18: 48.871113 | C18: 112.14 | D18: 232.96883 | E18: 48.433555 | F18: 813.38615 | G18: 15.12 | H18: 216.9044 | I18: 5.6608109 | J18: 95.873392 | K18: 97.02 | L18: 235.37365 | M18: 42.772744 | N18: 717.51276 | O18: 2.8659578 | P18: 1.0796683 | Q18: 1.7218781 | R18: 23.89018 | S18: 23.190007 | T18: 1600.1105 | U18: 65.22953 | V18: 13.483146 | W18: 10.90948
A19: 75 | B19: 51.411814 | C19: 97.02 | D19: 252.5694 | E19: 49.250753 | F19: 860.85384 | G19: 12.15 | H19: 232.14326 | I19: 5.21049 | J19: 90.737585 | K19: 84.87 | L19: 255.35995 | M19: 44.040263 | N19: 770.11625 | O19: 2.8586679 | P19: 1.0191464 | Q19: 1.6705013 | R19: 23.307014 | S19: 23.246021 | T19: 1743.4516 | U19: 63.249925 | V19: 12.523191 | W19: 11.664271
A20: 81 | B20: 53.886485 | C20: 84.87 | D20: 272.51196 | E20: 50.155142 | F20: 909.95834 | G20: 84.87 | H20: 272.51196 | I20: 50.155142 | J20: 909.95834 | K20: - | L20: - | M20: - | N20: - | O20: - | P20: - | Q20: 1.6222528 | R20: - | S20: 23.250539 | T20: 1883.2937 | U20: 62.121819 | V20: - | W20: -
A22: Distribution des volumes produits par classe de grosseur
A23: Age | B23: Hdom | C23: Classes de grosseur - Volume sur pied | K23: VMV | M23: Classes de grosseur - Volume prélevés | U23: VMP | W23: VMA totale
C24: 20-40 | D24: 40-60 | E24: 60-70 | F24: 70-90 | G24: 90-120 | H24: 120-150 | I24: 150-180 | J24: 180+ | K24: VMV | L24: VMA | M24: 20-40 | N24: 40-60 | O24: 60-70 | P24: 70-90 | Q24: 90-120 | R24: 120-150 | S24: 150-180 | T24: 180+ | U24: VMP | V24: VMA
A25: années | B25: m | C25: m³/ha | D25: m³/ha | E25: m³/ha | F25: m³/ha | G25: m³/ha | H25: m³/ha | I25: m³/ha | J25: m³/ha | K25: € /ha | L25: € /ha | M25: m³/ha | N25: m³/ha | O25: m³/ha | P25: m³/ha | Q25: m³/ha | R25: m³/ha | S25: m³/ha | T25: m³/ha | U25: € /ha | V25: € /ha | W25: € /ha
A26: 15 | B26: 13.523098 | C26: 28.602416 | D26: 89.732237 | E26: 26.336633 | F26: 5.245834 | G26: 0 | H26: 0 | I26: 0 | J26: 0 | K26: 2213.9234 | L26: 1644.9777 | M26: 10.457778 | N26: 25.350964 | O26: 7.7921332 | P26: 1.5184598 | Q26: 0 | R26: 0 | S26: 0 | T26: 0 | U26: 588.7657 | V26: 437.46158 | W26: 1644.9777
A27: 21 | B27: 18.672501 | C27: 6.9752345 | D27: 68.751641 | E27: 59.874877 | F27: 101.0814 | G27: 24.200647 | H27: 0 | I27: 0 | J27: 0 | K27: 7861.8803 | L27: 5187.0785 | M27: 4.9739278 | N27: 30.17616 | O27: 13.632126 | P27: 16.251602 | Q27: 3.8011019 | R27: 0 | S27: 0 | T27: 0 | U27: 1483.6938 | V27: 978.90529 | W27: 5624.5401
A28: 27 | B28: 23.580745 | C28: 0.82214881 | D28: 21.02 | E28: 29.768175 | F28: 121.86299 | G28: 171.64936 | H28: 13.316702 | I28: 0 | J28: 0 | K28: 15893.178 | L28: 9311.2096 | M28: 0.64809636 | N28: 12.836284 | O28: 13.375592 | P28: 25.406641 | Q28: 23.445923 | R28: 1.6680153 | S28: 0 | T28: 0 | U28: 2624.738 | V28: 1537.7344 | W28: 10727.576
A29: 33 | B29: 28.157502 | C29: 0 | D29: 4.9444559 | E29: 9.6685309 | F29: 55.484086 | G29: 224.69543 | H29: 157.17538 | I29: 0 | J29: 0 | K29: 24707.193 | L29: 12853.391 | M29: 0 | N29: 4.0150067 | O29: 6.2346333 | P29: 23.672059 | Q29: 39.506321 | R29: 19.447909 | S29: 0 | T29: 0 | U29: 4119.5863 | V29: 2143.1272 | W29: 15807.493
A30: 39 | B30: 32.385359 | C30: 0 | D30: 0.21075352 | E30: 1.9173288 | F30: 16.080985 | G30: 136.17056 | H30: 262.68526 | I30: 112.00825 | J30: 0 | K30: 33790.351 | L30: 15609.393 | M30: 0 | N30: 0.15646747 | O30: 1.6323702 | P30: 10.823469 | Q30: 47.607424 | R30: 31.609267 | S30: 10.250569 | T30: 0 | U30: 5319.9345 | V30: 2457.5343 | W30: 20706.621
A31: 45 | B31: 36.28041 | C31: 0 | D31: 0 | E31: 0 | F31: 2.2834967 | G31: 38.914213 | H31: 221.6689 | I31: 262.19793 | J31: 67.462929 | K31: 42698.064 | L31: 17514.61 | M31: 0 | N31: 0 | O31: 0 | P31: 1.9489203 | Q31: 20.533433 | R31: 44.713596 | S31: 26.059715 | T31: 8.7203506 | U31: 6231.2456 | V31: 2556.037 | W31: 25069.372
A32: 51 | B32: 39.820658 | C32: 0 | D32: 0 | E32: 0 | F32: 0 | G32: 6.6146199 | H32: 90.746585 | I32: 300.18612 | J32: 253.6268 | K32: 51070.905 | L32: 18602.221 | M32: 0 | N32: 0 | O32: 0 | P32: 0 | Q32: 4.1006592 | R32: 39.218279 | S32: 36.88064 | T32: 19.366125 | U32: 6630.3975 | V32: 2415.076 | W32: 28713.02
A33: 57 | B33: 43.08956 | C33: 0 | D33: 0 | E33: 0 | F33: 0 | G33: 0.15470266 | H33: 21.312634 | I33: 169.42119 | J33: 516.46891 | K33: 58489.123 | L33: 18917.569 | M33: 0 | N33: 0 | O33: 0 | P33: 0 | Q33: 0.15470266 | R33: 12.785211 | S33: 43.366427 | T33: 41.788543 | U33: 7048.723 | V33: 2279.8205 | W33: 31443.444
A34: 63 | B34: 46.081128 | C34: 0 | D34: 0 | E34: 0 | F34: 0 | G34: 0 | H34: 2.8584851 | I34: 46.524566 | J34: 711.06621 | K34: 64389.446 | L34: 18492.851 | M34: 0 | N34: 0 | O34: 0 | P34: 0 | Q34: 0 | R34: 2.3789395 | S34: 22.894611 | T34: 69.527419 | U34: 7133.7341 | V34: 2048.8308 | W34: 33298.547
A35: 69 | B35: 48.871113 | C35: 0 | D35: 0 | E35: 0 | F35: 0 | G35: 0 | H35: 0 | I35: 7.2767393 | J35: 804.88555 | K35: 69176.802 | L35: 17642.033 | M35: 0 | N35: 0 | O35: 0 | P35: 0 | Q35: 0 | R35: 0 | S35: 5.0195522 | T35: 89.629981 | U35: 7297.6922 | V35: 1861.1171 | W35: 34496.56
A36: 75 | B36: 51.411814 | C36: 0 | D36: 0 | E36: 0 | F36: 0 | G36: 0 | H36: 0 | I36: 0 | J36: 860.72542 | K36: 73376.842 | L36: 16616.752 | M36: 0 | N36: 0 | O36: 0 | P36: 0 | Q36: 0 | R36: 0 | S36: 0 | T36: 90.609165 | U36: 7022.2103 | V36: 1590.2337 | W36: 35332.396
A37: 81 | B37: 53.886485 | C37: 0 | D37: 0 | E37: 0 | F37: 0 | G37: 0 | H37: 0 | I37: 0 | J37: 909.95834 | K37: 77573.948 | L37: 15599.188 | M37: 0 | N37: 0 | O37: 0 | P37: 0 | Q37: 0 | R37: 0 | S37: 0 | T37: 909.95834 | U37: 77573.948 | V37: 15599.188 | W37: 35905.065
A38: Total | B38: - | C38: - | D38: - | E38: - | F38: - | G38: - | H38: - | I38: - | J38: - | K38: - | L38: - | M38: 16.079802 | N38: 72.534882 | O38: 42.666854 | P38: 79.621151 | Q38: 139.14956 | R38: 151.82122 | S38: 144.47151 | T38: 1229.5999 | U38: - | V38: 35905.065 | W38: -
W40: J. Perin, 2016
W41: (j.perin@ulg.ac.be)

Sheet Do2A
D1: Classe de productivité 2, plantation 2.5 x 2 m
A3: Caractéristiques : | E3: Essence : douglas | K3: Plantation : 2.5 x 2 (85% de reprise) | R3: Rotation : 6 ans
E4: Classe II (36 m à 50 ans) | K4: Cloisonnement : 1 ligne sur 9 | R4: Taux d'actualisation : 2 %
A5: Table de production
A6: Age | B6: Hdom | C6: Avant prélèvement | G6: Prélèvement | K6: Après prélèvement | O6: Accroissements | U6: h/d | V6: Ecl | W6: Dist
C7: Nha | D7: Cg | E7: Gha | F7: Vha | G7: Nha | H7: Cg | I7: Gha | J7: Vha | K7: Nha | L7: Cg | M7: Gha | N7: Vha | O7: ACC | P7: ACG | Q7: AMG | R7: ACV | S7: AMV | T7: PTV
A8: années | B8: m | C8: N/ha | D8: cm | E8: m²/ha | F8: m³/ha | G8: N/ha | H8: cm | I8: m²/ha | J8: m³/ha | K8: N/ha | L8: cm | M8: m²/ha | N8: m³/ha | O8: cm/an | P8: m²/ha/an | Q8: m²/ha/an | R8: m³/ha/an | S8: m³/ha/an | T8: m³/ha | V8: % | W8: m
A9: 17 | B9: 13.495068 | C9: 1613.1 | D9: 45.656417 | E9: 26.758088 | F9: 149.81209 | G9: 526.62 | H9: 44.250199 | I9: 8.2057436 | J9: 45.497988 | K9: 1086.48 | L9: 46.322657 | M9: 18.552344 | N9: 104.3141 | O9: 2.4693779 | P9: 2.2737884 | Q9: 1.5740052 | R9: 22.82808 | S9: 8.812476 | T9: 149.81209 | U9: 91.523259 | V9: 32.646457 | W9: 3.2600467
A10: 23 | B10: 18.057615 | C10: 1082.34 | D10: 61.138924 | E10: 32.195074 | F10: 241.28259 | G10: 355.32 | H10: 52.910064 | I10: 7.9156459 | J10: 56.680244 | K10: 727.02 | L10: 64.781497 | M10: 24.279428 | N10: 184.60234 | O10: 2.4701541 | P10: 2.035395 | Q10: 1.7565573 | R10: 24.527585 | S10: 12.468721 | T10: 286.78057 | U10: 87.570794 | V10: 32.828871 | W10: 3.9853045
A11: 29 | B11: 22.414717 | C11: 723.69 | D11: 79.602422 | E11: 36.491798 | F11: 331.76785 | G11: 203.4 | H11: 68.061957 | I11: 7.4980779 | J11: 66.274324 | K11: 520.29 | L11: 83.682408 | M11: 28.993721 | N11: 265.49353 | O11: 2.4829139 | P11: 1.8400344 | Q11: 1.8142479 | R11: 25.331592 | S11: 14.963658 | T11: 433.94608 | U11: 84.149003 | V11: 28.105957 | W11: 4.7109874
A12: 35 | B12: 26.490655 | C12: 517.68 | D12: 98.579891 | E12: 40.033927 | F12: 417.48308 | G12: 138.6 | H12: 85.036728 | I12: 7.9756566 | J12: 81.89196 | K12: 379.08 | L12: 103.08834 | M12: 32.05827 | N12: 335.59112 | O12: 2.5284447 | P12: 1.6599176 | Q12: 1.8186684 | R12: 25.230409 | S12: 16.741018 | T12: 585.93564 | U12: 80.729642 | V12: 26.773296 | W12: 5.5191125
A13: 41 | B13: 30.256225 | C13: 377.55 | D13: 118.25901 | E13: 42.017776 | F13: 486.97357 | G13: 92.7 | H13: 103.83254 | I13: 7.9531066 | J13: 91.445591 | K13: 284.85 | L13: 122.58827 | M13: 34.064669 | N13: 395.52798 | O13: 2.5790573 | P13: 1.5033175 | Q13: 1.7954366 | R13: 24.688657 | S13: 17.983368 | T13: 737.31809 | U13: 77.538198 | V13: 24.553039 | W13: 6.3668786
A14: 47 | B14: 33.733224 | C14: 284.04 | D14: 138.06261 | E14: 43.084574 | F14: 543.65992 | G14: 60.75 | H14: 122.18772 | I14: 7.2175789 | J14: 90.655016 | K14: 223.29 | L14: 142.07504 | M14: 35.866996 | N14: 453.00491 | O14: 2.6159358 | P14: 1.3729497 | Q14: 1.7581448 | R14: 24.056754 | S14: 18.839362 | T14: 885.45003 | U14: 74.591601 | V14: 21.387833 | W14: 7.1911781
A15: 53 | B15: 36.952182 | C15: 222.66 | D15: 157.77066 | E15: 44.104694 | F15: 597.34543 | G15: 41.85 | H15: 140.63798 | I15: 6.5870483 | J15: 89.018488 | K15: 180.81 | L15: 161.47731 | M15: 37.517645 | N15: 508.32694 | O15: 2.6283132 | P15: 1.2659619 | Q15: 1.7145378 | R15: 23.429348 | S15: 19.43001 | T15: 1029.7906 | U15: 71.891652 | V15: 18.795473 | W15: 7.9914109
A16: 59 | B16: 39.934652 | C16: 180.45 | D16: 177.24719 | E16: 45.113416 | F16: 648.90303 | G16: 30.06 | H16: 159.83387 | I16: 6.1110624 | J16: 87.815388 | K16: 150.39 | L16: 180.52646 | M16: 39.002354 | N16: 561.08764 | O16: 2.6271268 | P16: 1.175531 | Q16: 1.6689199 | R16: 22.805917 | S16: 19.836723 | T16: 1170.3666 | U16: 69.495857 | V16: 16.658354 | W16: 8.762443
A17: 65 | B17: 42.710928 | C17: 150.21 | D17: 196.28922 | E17: 46.05554 | F17: 697.92314 | G17: 22.14 | H17: 180.14229 | I17: 5.7174068 | J17: 86.784287 | K17: 128.07 | L17: 198.94779 | M17: 40.338133 | N17: 611.13886 | O17: 2.6104038 | P17: 1.1002254 | Q17: 1.6233763 | R17: 22.229423 | S17: 20.110802 | T17: 1307.2021 | U17: 67.444999 | V17: 14.739365 | W17: 9.49535
A18: 71 | B18: 45.291535 | C18: 128.07 | D18: 214.61022 | E18: 46.939486 | F18: 744.51539 | G18: 17.55 | H18: 195.09977 | I18: 5.3159488 | J18: 84.568192 | K18: 110.52 | L18: 217.54744 | M18: 41.623537 | N18: 659.9472 | O18: 2.6103616 | P18: 1.0348424 | Q18: 1.5791664 | R18: 21.684821 | S18: 20.289841 | T18: 1440.5787 | U18: 65.405298 | V18: 13.703443 | W18: 10.221491
A19: 77 | B19: 47.69457 | C19: 110.52 | D19: 233.20961 | E19: 47.832591 | F19: 790.05613 | G19: 13.5 | H19: 216.22374 | I19: 5.0226236 | J19: 83.689155 | K19: 97.02 | L19: 235.47605 | M19: 42.809968 | N19: 706.36697 | O19: 2.6047925 | P19: 0.97854222 | Q19: 1.5367515 | R19: 21.176728 | S19: 20.39854 | T19: 1570.6876 | U19: 63.631486 | V19: 12.214984 | W19: 10.90948
A20: 83 | B20: 49.91865 | C20: 97.02 | D20: 251.10481 | E20: 48.681221 | F20: 833.42734 | G20: 97.02 | H20: 251.10481 | I20: 48.681221 | J20: 833.42734 | K20: - | L20: - | M20: - | N20: - | O20: - | P20: - | Q20: 1.496399 | R20: - | S20: 20.454795 | T20: 1697.748 | U20: 62.453629 | V20: - | W20: -
A22: Distribution des volumes produits par classe de grosseur
A23: Age | B23: Hdom | C23: Classes de grosseur - Volume sur pied | K23: VMV | M23: Classes de grosseur - Volume prélevés | U23: VMP | W23: VMA totale
C24: 20-40 | D24: 40-60 | E24: 60-70 | F24: 70-90 | G24: 90-120 | H24: 120-150 | I24: 150-180 | J24: 180+ | K24: VMV | L24: VMA | M24: 20-40 | N24: 40-60 | O24: 60-70 | P24: 70-90 | Q24: 90-120 | R24: 120-150 | S24: 150-180 | T24: 180+ | U24: VMP | V24: VMA
A25: années | B25: m | C25: m³/ha | D25: m³/ha | E25: m³/ha | F25: m³/ha | G25: m³/ha | H25: m³/ha | I25: m³/ha | J25: m³/ha | K25: € /ha | L25: € /ha | M25: m³/ha | N25: m³/ha | O25: m³/ha | P25: m³/ha | Q25: m³/ha | R25: m³/ha | S25: m³/ha | T25: m³/ha | U25: € /ha | V25: € /ha | W25: € /ha
A26: 17 | B26: 13.495068 | C26: 28.660366 | D26: 88.825485 | E26: 26.820758 | F26: 5.1639838 | G26: 0 | H26: 0 | I26: 0 | J26: 0 | K26: 2210.6505 | L26: 1578.7638 | M26: 10.25974 | N26: 25.723368 | O26: 7.53448 | P26: 1.6389011 | Q26: 0 | R26: 0 | S26: 0 | T26: 0 | U26: 590.96371 | V26: 422.04416 | W26: 1578.7638
A27: 23 | B27: 18.057615 | C27: 7.8798013 | D27: 71.201219 | E27: 56.341519 | F27: 88.993735 | G27: 16.560897 | H27: 0 | I27: 0 | J27: 0 | K27: 6913.946 | L27: 4384.5198 | M27: 5.284985 | N27: 26.17605 | O27: 9.8564126 | P27: 12.673938 | Q27: 2.3834432 | R27: 0 | S27: 0 | T27: 0 | U27: 1150.793 | V27: 729.78222 | W27: 4806.5639
A28: 29 | B28: 22.414717 | C28: 1.2094617 | D28: 25.719708 | E28: 36.939562 | F28: 124.40288 | G28: 143.05733 | H28: 0 | I28: 0 | J28: 0 | K28: 13866.77 | L28: 7808.5491 | M28: 0.94952904 | N28: 13.826036 | O28: 13.555064 | P28: 19.334017 | Q28: 18.170767 | R28: 0 | S28: 0 | T28: 0 | U28: 2063.7861 | V28: 1162.1434 | W28: 8960.3755
A29: 35 | B29: 26.490655 | C29: 0.03666464 | D29: 6.7020027 | E29: 13.706016 | F29: 74.625471 | G29: 219.89976 | H29: 101.87156 | I29: 0 | J29: 0 | K29: 21719.478 | L29: 10860.339 | M29: 0.03666464 | N29: 5.0263573 | O29: 7.6888429 | P29: 25.35212 | Q29: 30.779793 | R29: 12.366576 | S29: 0 | T29: 0 | U29: 3388.2378 | V29: 1694.2125 | W29: 13174.309
A30: 41 | B30: 30.256225 | C30: 0 | D30: 0.93742308 | E30: 2.971381 | F30: 26.191632 | G30: 179.7275 | H30: 226.92915 | I30: 49.472313 | J30: 0 | K30: 29343.774 | L30: 13028.935 | M30: 0 | N30: 0.8390242 | O30: 2.038713 | P30: 13.948022 | Q30: 43.366052 | R30: 23.119484 | S30: 7.3901207 | T30: 0 | U30: 4543.3551 | V30: 2017.2961 | W30: 17037.118
A31: 47 | B31: 33.733224 | C31: 0 | D31: 0 | E31: 0.23707501 | F31: 6.0709001 | G31: 76.232964 | H31: 256.69966 | I31: 198.0938 | J31: 5.5942703 | K31: 36911.776 | L31: 14553.145 | M31: 0 | N31: 0 | O31: 0.19678585 | P31: 4.1029114 | Q31: 31.271465 | R31: 35.306628 | S31: 18.735686 | T31: 0.31028455 | U31: 5097.6242 | V31: 2009.8319 | W31: 20578.624
A32: 53 | B32: 36.952182 | C32: 0 | D32: 0 | E32: 0 | F32: 0.66367442 | G32: 20.82507 | H32: 165.26032 | I32: 287.82114 | J32: 122.05521 | K32: 44590.103 | L32: 15610.951 | M32: 0 | N32: 0 | O32: 0 | P32: 0.59203953 | Q32: 12.176128 | R32: 42.041761 | S32: 24.773671 | T32: 8.7148824 | U32: 5532.6336 | V32: 1936.9696 | W32: 23646.262
A33: 59 | B33: 39.934652 | C33: 0 | D33: 0 | E33: 0 | F33: 0 | G33: 2.8088997 | H33: 54.443978 | I33: 276.44535 | J33: 314.55435 | K33: 51842.118 | L33: 16116.569 | M33: 0 | N33: 0 | O33: 0 | P33: 0 | Q33: 2.0229443 | R33: 24.019816 | S33: 42.240254 | T33: 18.881918 | U33: 5957.4453 | V33: 1852.0381 | W33: 26088.849
A34: 65 | B34: 42.710928 | C34: 0 | D34: 0 | E34: 0 | F34: 0 | G34: 0 | H34: 11.983605 | I34: 140.16529 | J34: 545.07475 | K34: 58051.267 | L34: 16025.092 | M34: 0 | N34: 0 | O34: 0 | P34: 0 | Q34: 0 | R34: 5.0942593 | S34: 41.636488 | T34: 39.354037 | U34: 6270.1477 | V34: 1730.8786 | W34: 27849.41
A35: 71 | B35: 45.291535 | C35: 0 | D35: 0 | E35: 0 | F35: 0 | G35: 0 | H35: 1.8662814 | I35: 37.523315 | J35: 704.32981 | K35: 63056.586 | L35: 15456.753 | M35: 0 | N35: 0 | O35: 0 | P35: 0 | Q35: 0 | R35: 1.6266777 | S35: 18.156987 | T35: 63.988542 | U35: 6327.7017 | V35: 1551.0786 | W35: 29011.949
A36: 77 | B36: 47.69457 | C36: 0 | D36: 0 | E36: 0 | F36: 0 | G36: 0 | H36: 0 | I36: 5.6274807 | J36: 783.30977 | K36: 67210.474 | L36: 14629.306 | M36: 0 | N36: 0 | O36: 0 | P36: 0 | Q36: 0 | R36: 0 | S36: 3.8325956 | T36: 78.737684 | U36: 6370.4522 | V36: 1386.6186 | W36: 29735.581
A37: 83 | B37: 49.91865 | C37: 0 | D37: 0 | E37: 0 | F37: 0 | G37: 0 | H37: 0 | I37: 0 | J37: 833.42734 | K37: 71049.681 | L37: 13732.445 | M37: 0 | N37: 0 | O37: 0 | P37: 0 | Q37: 0 | R37: 0 | S37: 0 | T37: 833.42734 | U37: 71049.681 | V37: 13732.445 | W37: 30225.339
A38: Total | B38: - | C38: - | D38: - | E38: - | F38: - | G38: - | H38: - | I38: - | J38: - | K38: - | L38: - | M38: 16.530919 | N38: 71.590836 | O38: 40.870299 | P38: 77.641949 | Q38: 140.17059 | R38: 143.5752 | S38: 156.7658 | T38: 1043.4147 | U38: - | V38: 30225.339 | W38: -
W40: J. Perin, 2016
W41: (j.perin@ulg.ac.be)

Sheet Do3A
D1: Classe de productivité 3, plantation 2.5 x 2 m
A3: Caractéristiques : | E3: Essence : douglas | K3: Plantation : 2.5 x 2 (85% de reprise) | R3: Rotation : 6 ans
E4: Classe III (32 m à 50 ans) | K4: Cloisonnement : 1 ligne sur 9 | R4: Taux d'actualisation : 2 %
A5: Table de production
A6: Age | B6: Hdom | C6: Avant prélèvement | G6: Prélèvement | K6: Après prélèvement | O6: Accroissements | U6: h/d | V6: Ecl | W6: Dist
C7: Nha | D7: Cg | E7: Gha | F7: Vha | G7: Nha | H7: Cg | I7: Gha | J7: Vha | K7: Nha | L7: Cg | M7: Gha | N7: Vha | O7: ACC | P7: ACG | Q7: AMG | R7: ACV | S7: AMV | T7: PTV
A8: années | B8: m | C8: N/ha | D8: cm | E8: m²/ha | F8: m³/ha | G8: N/ha | H8: cm | I8: m²/ha | J8: m³/ha | K8: N/ha | L8: cm | M8: m²/ha | N8: m³/ha | O8: cm/ha/an | P8: m²/ha/an | Q8: m²/ha/an | R8: m³/ha/an | S8: m³/ha/an | T8: m³/ha | V8: % | W8: m
A9: 19 | B9: 13.080435 | C9: 1613.765 | D9: 44.377804 | E9: 25.290769 | F9: 136.83415 | G9: 526.835 | H9: 43.003643 | I9: 7.7530976 | J9: 41.49067 | K9: 1086.93 | L9: 45.028773 | M9: 17.537671 | N9: 95.343476 | O9: 2.2522022 | P9: 2.0053328 | Q9: 1.3310931 | R9: 19.36152 | S9: 7.2017972 | T9: 136.83415 | U9: 91.260312 | V9: 32.646327 | W9: 3.2593717
A10: 25 | B10: 17.075217 | C10: 1084.23 | D10: 58.541986 | E10: 29.569669 | F10: 211.5126 | G10: 290.7 | H10: 49.813943 | I10: 5.740332 | J10: 38.758456 | K10: 793.53 | L10: 61.429819 | M10: 23.829337 | N10: 172.75414 | O10: 2.2026628 | P10: 1.8680911 | Q10: 1.4929106 | R10: 21.484257 | S10: 10.120131 | T10: 253.00327 | U10: 87.324656 | V10: 26.811654 | W10: 3.8146352
A11: 31 | B11: 20.921891 | C11: 790.2 | D11: 74.645796 | E11: 35.037883 | F11: 301.65968 | G11: 208.89 | H11: 63.576642 | I11: 6.718974 | J11: 55.902145 | K11: 581.31 | L11: 78.241884 | M11: 28.318909 | N11: 245.75754 | O11: 2.2140812 | P11: 1.7067952 | Q11: 1.5655262 | R11: 22.279356 | S11: 12.319639 | T11: 381.90881 | U11: 84.006232 | V11: 26.43508 | W11: 4.4568784
A12: 37 | B12: 24.535271 | C12: 578.43 | D12: 91.526371 | E12: 38.559681 | F12: 379.43367 | G12: 147.96 | H12: 79.015558 | I12: 7.3512244 | J12: 70.951494 | K12: 430.47 | L12: 95.448615 | M12: 31.208456 | N12: 308.48218 | O12: 2.2583982 | P12: 1.5504694 | Q12: 1.5884347 | R12: 22.267357 | S12: 13.934728 | T12: 515.58494 | U12: 80.755314 | V12: 25.579586 | W12: 5.1792066
A13: 43 | B13: 27.900045 | C13: 428.49 | D13: 108.999 | E13: 40.511273 | F13: 442.08632 | G13: 102.87 | H13: 95.050115 | I13: 7.3957832 | J13: 79.715238 | K13: 325.62 | L13: 113.04855 | M13: 33.11549 | N13: 362.37108 | O13: 2.3092004 | P13: 1.4127114 | Q13: 1.5831372 | R13: 21.877708 | S13: 15.097421 | T13: 649.18909 | U13: 77.533573 | V13: 24.007561 | W13: 5.9549641
A14: 49 | B14: 31.037064 | C14: 324.54 | D14: 126.90375 | E14: 41.591758 | F14: 493.63733 | G14: 68.49 | H14: 111.29725 | I14: 6.7512806 | J14: 79.532941 | K14: 256.05 | L14: 130.76291 | M14: 34.840477 | N14: 414.10439 | O14: 2.3514914 | P14: 1.300622 | Q14: 1.5622688 | R14: 21.453762 | S14: 15.92766 | T14: 780.45533 | U14: 74.56687 | V14: 21.103716 | W14: 6.7154063
A15: 55 | B15: 33.954785 | C15: 255.33 | D15: 144.87186 | E15: 42.644209 | F15: 542.82696 | G15: 46.89 | H15: 129.57078 | I15: 6.2644728 | J15: 79.561728 | K15: 208.44 | L15: 148.09629 | M15: 36.379737 | N15: 463.26524 | O15: 2.3653497 | P15: 1.2020553 | Q15: 1.5337255 | R15: 20.935077 | S15: 16.530507 | T15: 909.17791 | U15: 72.028883 | V15: 18.36447 | W15: 7.4429337
A16: 61 | B16: 36.672019 | C16: 207.99 | D16: 162.28839 | E16: 43.592069 | F16: 588.8757 | G16: 34.38 | H16: 145.07872 | I16: 5.7584216 | J16: 77.583732 | K16: 173.61 | L16: 165.48425 | M16: 37.833647 | N16: 511.29197 | O16: 2.3740752 | P16: 1.1206933 | Q16: 1.5011022 | R16: 20.466509 | S16: 16.963744 | T16: 1034.7884 | U16: 69.619039 | V16: 16.529641 | W16: 8.1554385
A17: 67 | B17: 39.227338 | C17: 173.34 | D17: 179.7287 | E17: 44.557806 | F17: 634.09102 | G17: 25.38 | H17: 163.95269 | I17: 5.4289874 | J17: 77.342056 | K17: 147.96 | L17: 182.29768 | M17: 39.128819 | N17: 556.74896 | O17: 2.362135 | P17: 1.0534469 | Q17: 1.4670357 | R17: 20.040722 | S17: 17.277424 | T17: 1157.5874 | U17: 67.601693 | V17: 14.641745 | W17: 8.8341043
A18: 73 | B18: 41.618617 | C18: 147.96 | D18: 196.47049 | E18: 45.4495 | F18: 676.99329 | G18: 19.8 | H18: 179.86397 | I18: 5.0973408 | J18: 76.083532 | K18: 128.16 | L18: 198.9125 | M18: 40.35216 | N18: 600.90976 | O18: 2.3624415 | P18: 0.99266005 | Q18: 1.4330421 | R18: 19.6044 | S18: 17.504545 | T18: 1277.8318 | U18: 65.731787 | V18: 13.381995 | W18: 9.4920154
A19: 79 | B19: 43.872513 | C19: 128.16 | D19: 213.08715 | E19: 46.30812 | F19: 718.53616 | G19: 15.75 | H19: 196.25552 | I19: 4.8274131 | J19: 75.160681 | K19: 112.41 | L19: 215.34041 | M19: 41.480707 | N19: 643.37548 | O19: 2.3621414 | P19: 0.93997899 | Q19: 1.3995954 | R19: 19.202582 | S19: 17.664027 | T19: 1395.4582 | U19: 64.005435 | V19: 12.289326 | W19: 10.135197
A20: 85 | B20: 46.00218 | C20: 112.41 | D20: 229.51326 | E20: 47.120581 | F20: 758.59098 | G20: 112.41 | H20: 229.51326 | I20: 47.120581 | J20: 758.59098 | K20: - | L20: - | M20: - | N20: - | O20: - | P20: - | Q20: 1.3671519 | R20: - | S20: 17.772631 | T20: 1510.6736 | U20: 62.968088 | V20: - | W20: -
A22: Distribution des volumes produits par classe de grosseur
A23: Age | B23: Hdom | C23: Classes de grosseur - Volume sur pied | K23: VMV | M23: Classes de grosseur - Volume prélevés | U23: VMP | W23: VMA totale
C24: 20-40 | D24: 40-60 | E24: 60-70 | F24: 70-90 | G24: 90-120 | H24: 120-150 | I24: 150-180 | J24: 180+ | K24: VMV | L24: VMA | M24: 20-40 | N24: 40-60 | O24: 60-70 | P24: 70-90 | Q24: 90-120 | R24: 120-150 | S24: 150-180 | T24: 180+ | U24: VMP | V24: VMA
A25: années | B25: m | C25: m³/ha | D25: m³/ha | E25: m³/ha | F25: m³/ha | G25: m³/ha | H25: m³/ha | I25: m³/ha | J25: m³/ha | K25: € /ha | L25: € /ha | M25: m³/ha | N25: m³/ha | O25: m³/ha | P25: m³/ha | Q25: m³/ha | R25: m³/ha | S25: m³/ha | T25: m³/ha | U25: € /ha | V25: € /ha | W25: € /ha
A26: 19 | B26: 13.080435 | C26: 29.931972 | D26: 82.006077 | E26: 22.481166 | F26: 2.1070437 | G26: 0 | H26: 0 | I26: 0 | J26: 0 | K26: 1893.9574 | L26: 1300.0706 | M26: 10.422325 | N26: 23.840316 | O26: 6.2731292 | P26: 0.64701276 | Q26: 0 | R26: 0 | S26: 0 | T26: 0 | U26: 503.6038 | V26: 345.68914 | W26: 1300.0706
A27: 25 | B27: 17.075217 | C27: 8.9068573 | D27: 73.908179 | E27: 52.587682 | F27: 70.814837 | G27: 5.098989 | H27: 0 | I27: 0 | J27: 0 | K27: 5513.655 | L27: 3360.7429 | M27: 5.0837315 | N27: 19.077189 | O27: 6.0413518 | P27: 7.8687344 | Q27: 0.49139578 | R27: 0 | S27: 0 | T27: 0 | U27: 708.69417 | V27: 431.97098 | W27: 3706.4321
A28: 31 | B28: 20.921891 | C28: 1.8413043 | D28: 32.688201 | E28: 46.289808 | F28: 126.09133 | G28: 94.407295 | H28: 0 | I28: 0 | J28: 0 | K28: 11721.333 | L28: 6344.1242 | M28: 1.3852037 | N28: 15.15135 | O28: 12.880441 | P28: 15.909393 | Q28: 10.234015 | R28: 0 | S28: 0 | T28: 0 | U28: 1561.2701 | V28: 845.03115 | W28: 7121.7843
A29: 37 | B29: 24.535271 | C29: 0.1264835 | D29: 10.0484 | E29: 19.687236 | F29: 103.95418 | G29: 199.02173 | H29: 46.081846 | I29: 0 | J29: 0 | K29: 18348.991 | L29: 8818.7256 | M29: 0.10222306 | N29: 6.5234566 | O29: 9.2455575 | P29: 26.511749 | Q29: 21.990187 | R29: 6.0645257 | S29: 0 | T29: 0 | U29: 2689.4137 | V29: 1292.5616 | W29: 10441.417
A30: 43 | B30: 27.900045 | C30: 0 | D30: 1.8291422 | E30: 5.4911358 | F30: 43.581494 | G30: 214.9898 | H30: 173.37512 | I30: 2.2629821 | J30: 0 | K30: 24808.012 | L30: 10587.284 | M30: 0 | N30: 1.4968317 | O30: 3.5227035 | P30: 19.387165 | Q30: 36.760804 | R30: 17.613962 | S30: 0.37712773 | T30: 0 | U30: 3653.6164 | V30: 1559.2493 | W30: 13502.537
A31: 49 | B31: 31.037064 | C31: 0 | D31: 0 | E31: 1.1533046 | F31: 12.785467 | G31: 134.65155 | H31: 246.37981 | I31: 98.035631 | J31: 0 | K31: 31401.299 | L31: 11899.787 | M31: 0 | N31: 0 | O31: 0.85955726 | P31: 8.0289985 | Q31: 38.857325 | R31: 21.547181 | S31: 9.6083113 | T31: 0 | U31: 4131.5631 | V31: 1565.6907 | W31: 16374.29
A32: 55 | B32: 33.954785 | C32: 0 | D32: 0 | E32: 0 | F32: 2.1093908 | G32: 46.149591 | H32: 240.73816 | I32: 226.84898 | J32: 26.288878 | K32: 38095.546 | L32: 12819.313 | M32: 0 | N32: 0 | O32: 0 | P32: 1.8478315 | Q32: 19.260416 | R32: 37.021091 | S32: 18.139234 | T32: 2.6011945 | U32: 4676.7678 | V32: 1573.7522 | W32: 18859.506
A33: 61 | B33: 36.672019 | C33: 0 | D33: 0 | E33: 0 | F33: 0 | G33: 8.3396385 | H33: 141.02574 | I33: 291.2073 | J33: 147.71838 | K33: 44759.399 | L33: 13374.383 | M33: 0 | N33: 0 | O33: 0 | P33: 0 | Q33: 5.8794845 | R33: 41.239968 | S33: 19.168371 | T33: 10.711266 | U33: 4925.5827 | V33: 1471.7944 | W33: 20988.328
A34: 67 | B34: 39.227338 | C34: 0 | D34: 0 | E34: 0 | F34: 0 | G34: 0.54206918 | H34: 42.338339 | I34: 260.2322 | J34: 330.32078 | K34: 51020.379 | L34: 13537.304 | M34: 0 | N34: 0 | O34: 0 | P34: 0 | Q34: 0.54206918 | R34: 19.488906 | S34: 36.428072 | T34: 20.225376 | U34: 5312.5143 | V34: 1409.5764 | W34: 22623.043
A35: 73 | B35: 41.618617 | C35: 0 | D35: 0 | E35: 0 | F35: 0 | G35: 0 | H35: 5.9779483 | I35: 138.75742 | J35: 531.60358 | K35: 56398.071 | L35: 13287.758 | M35: 0 | N35: 0 | O35: 0 | P35: 0 | Q35: 0 | R35: 4.1745884 | S35: 39.020246 | T35: 32.234352 | U35: 5480.0549 | V35: 1291.1371 | W35: 23783.074
A36: 79 | B36: 43.872513 | C36: 0 | D36: 0 | E36: 0 | F36: 0 | G36: 0 | H36: 0.24003559 | I36: 35.758572 | J36: 681.85134 | K36: 60897.079 | L36: 12740.395 | M36: 0 | N36: 0 | O36: 0 | P36: 0 | Q36: 0 | R36: 0.24003559 | S36: 17.743957 | T36: 56.490472 | U36: 5634.4907 | V36: 1178.8026 | W36: 24526.848
A37: 85 | B37: 46.00218 | C37: 0 | D37: 0 | E37: 0 | F37: 0 | G37: 0 | H37: 0 | I37: 3.1952212 | J37: 755.39576 | K37: 64643.52 | L37: 12009.098 | M37: 0 | N37: 0 | O37: 0 | P37: 0 | Q37: 0 | R37: 0 | S37: 3.1952212 | T37: 755.39576 | U37: 64643.52 | V37: 12009.098 | W37: 24974.354
A38: Total | B38: - | C38: - | D38: - | E38: - | F38: - | G38: - | H38: - | I38: - | J38: - | K38: - | L38: - | M38: 16.993484 | N38: 66.089142 | O38: 38.82274 | P38: 80.200885 | Q38: 134.0157 | R38: 147.39026 | S38: 143.68054 | T38: 877.65842 | U38: - | V38: 24974.354 | W38: -
W40: J. Perin, 2016
W41: (j.perin@ulg.ac.be)

Sheet Do4A
D1: Classe de productivité 4, plantation 2.5 x 2 m
A3: Caractéristiques : | E3: Essence : douglas | K3: Plantation : 2.5 x 2 (85% de reprise) | R3: Rotation : 6 ans
E4: Classe IV (28 m à 50 ans) | K4: Cloisonnement : 1 ligne sur 9 | R4: Taux d'actualisation : 2 %
A5: Table de production
A6: Age | B6: Hdom | C6: Avant prélèvement | G6: Prélèvement | K6: Après prélèvement | O6: Accroissements | U6: h/d | V6: Ecl | W6: Dist
C7: Nha | D7: Cg | E7: Gha | F7: Vha | G7: Nha | H7: Cg | I7: Gha | J7: Vha | K7: Nha | L7: Cg | M7: Gha | N7: Vha | O7: ACC | P7: ACG | Q7: AMG | R7: ACV | S7: AMV | T7: PTV
A8: années | B8: m | C8: N/ha | D8: cm | E8: m²/ha | F8: m³/ha | G8: N/ha | H8: cm | I8: m²/ha | J8: m³/ha | K8: N/ha | L8: cm | M8: m²/ha | N8: m³/ha | O8: cm/ha/an | P8: m²/ha/an | Q8: m²/ha/an | R8: m³/ha/an | S8: m³/ha/an | T8: m³/ha | V8: % | W8: m
A9: 23 | B9: 13.482303 | C9: 1612.815 | D9: 45.696587 | E9: 26.800459 | F9: 150.02779 | G9: 526.515 | H9: 44.187088 | I9: 8.1807224 | J9: 45.233193 | K9: 1086.3 | L9: 46.410559 | M9: 18.619736 | N9: 104.7946 | O9: 1.9383769 | P9: 1.7409701 | Q9: 1.1652373 | R9: 16.884272 | S9: 6.5229476 | T9: 150.02779 | U9: 91.263507 | V9: 32.645716 | W9: 3.2603167
A10: 29 | B10: 16.906645 | C10: 1084.23 | D10: 58.040821 | E10: 29.065557 | F10: 206.10023 | G10: 273.87 | H10: 49.492052 | I10: 5.3383313 | J10: 35.684612 | K10: 810.36 | L10: 60.658185 | M10: 23.727225 | N10: 170.41562 | O10: 1.9222587 | P10: 1.6262724 | Q10: 1.2843545 | R10: 18.333722 | S10: 8.6666698 | T10: 251.33342 | U10: 87.562447 | V10: 25.259401 | W10: 3.7748151
A11: 35 | B11: 20.218879 | C11: 807.39 | D11: 72.191737 | E11: 33.48486 | F11: 280.41795 | G11: 189.9 | H11: 60.488453 | I11: 5.5291714 | J11: 44.36776 | K11: 617.49 | L11: 75.426692 | M11: 27.955688 | N11: 236.05019 | O11: 1.927402 | P11: 1.5138576 | Q11: 1.342969 | R11: 19.131742 | S11: 10.323879 | T11: 361.33576 | U11: 84.213532 | V11: 23.520232 | W11: 4.3243389
A12: 41 | B12: 23.356367 | C12: 615.06 | D12: 86.991104 | E12: 37.038834 | F12: 350.84064 | G12: 145.35 | H12: 74.400205 | I12: 6.4025567 | J12: 59.227071 | K12: 469.71 | L12: 90.533232 | M12: 30.636277 | N12: 291.61357 | O12: 1.9687183 | P12: 1.3943386 | Q12: 1.3679771 | R12: 19.230879 | S12: 11.612834 | T12: 476.12621 | U12: 81.048904 | V12: 23.631841 | W12: 4.9581514
A13: 47 | B13: 26.295428 | C13: 467.91 | D13: 102.34554 | E13: 39.002309 | F13: 406.99884 | G13: 105.03 | H13: 89.146922 | I13: 6.6422651 | J13: 68.278332 | K13: 362.88 | L13: 105.85904 | M13: 32.360044 | N13: 338.72051 | O13: 2.0209561 | P13: 1.283074 | Q13: 1.3713424 | R13: 18.985381 | S13: 12.585351 | T13: 591.51148 | U13: 78.037283 | V13: 22.446624 | W13: 5.6409619
A14: 53 | B14: 29.060241 | C14: 361.62 | D14: 117.98478 | E14: 40.058488 | F14: 452.6328 | G14: 71.19 | H14: 104.01117 | I14: 6.1287103 | J14: 68.609374 | K14: 290.43 | L14: 121.16431 | M14: 33.929778 | N14: 384.02342 | O14: 2.0504388 | P14: 1.1875376 | Q14: 1.3613497 | R14: 18.663185 | S14: 13.309882 | T14: 705.42377 | U14: 75.348461 | V14: 19.686411 | W14: 6.3054189
A15: 59 | B15: 31.660941 | C15: 289.62 | D15: 133.46694 | E15: 41.055003 | F15: 496.00253 | G15: 51.12 | H15: 118.15602 | I15: 5.6792727 | J15: 68.222487 | K15: 238.5 | L15: 136.5254 | M15: 35.375731 | N15: 427.78005 | O15: 2.0766007 | P15: 1.1067149 | Q15: 1.3436739 | R15: 18.328633 | S15: 13.854286 | T15: 817.40288 | U15: 72.855148 | V15: 17.650715 | W15: 6.9580972
A16: 65 | B16: 34.106295 | C16: 237.87 | D16: 148.985 | E16: 42.01602 | F16: 537.75184 | G16: 36.99 | H16: 134.57939 | I16: 5.3312807 | J16: 68.206602 | K16: 200.88 | L16: 151.48837 | M16: 36.684739 | N16: 469.54524 | O16: 2.0781564 | P16: 1.0382973 | Q16: 1.3218008 | R16: 17.995416 | S16: 14.267303 | T16: 927.37467 | U16: 70.730237 | V16: 15.550511 | W16: 7.5816954
A17: 71 | B17: 36.404045 | C17: 200.61 | D17: 163.95731 | E17: 42.914523 | F17: 577.51774 | G17: 28.62 | H17: 148.16475 | I17: 4.9997646 | J17: 67.242312 | K17: 171.99 | L17: 166.43991 | M17: 37.914758 | N17: 510.27542 | O17: 2.0813089 | P17: 0.97998923 | Q17: 1.2978427 | R17: 17.692783 | S17: 14.582354 | T17: 1035.3472 | U17: 68.713495 | V17: 14.266487 | W17: 8.1937571
A18: 77 | B18: 38.591413 | C18: 171.9 | D18: 178.92777 | E18: 43.794694 | F18: 616.43212 | G18: 22.41 | H18: 163.21084 | I18: 4.750398 | J18: 66.873764 | K18: 149.49 | L18: 181.1664 | M18: 39.044295 | N18: 549.55836 | O18: 2.0824142 | P18: 0.92853993 | Q18: 1.2730749 | R18: 17.398289 | S18: 14.824726 | T18: 1141.5039 | U18: 66.921073 | V18: 13.036649 | W18: 8.7887804
A19: 83 | B19: 40.676788 | C19: 149.49 | D19: 193.66089 | E19: 44.615535 | F19: 653.94809 | G19: 18.09 | H19: 176.24198 | I19: 4.4714401 | J19: 65.652027 | K19: 131.4 | L19: 195.93774 | M19: 40.144095 | N19: 588.29607 | O19: 2.0890126 | P19: 0.8833808 | Q19: 1.2481688 | R19: 17.129291 | S19: 15.010766 | T19: 1245.8936 | U19: 65.219646 | V19: 12.101144 | W19: 9.3742601
A20: 89 | B20: 42.661906 | C20: 131.4 | D20: 208.47181 | E20: 45.44438 | F20: 691.07181 | G20: 131.4 | H20: 208.47181 | I20: 45.44438 | J20: 691.07181 | K20: - | L20: - | M20: - | N20: - | O20: - | P20: - | Q20: 1.2235763 | R20: - | S20: 15.153588 | T20: 1348.6693 | U20: 64.289905 | V20: - | W20: -
A22: Distribution des volumes produits par classe de grosseur
A23: Age | B23: Hdom | C23: Classes de grosseur - Volume sur pied | K23: VMV | M23: Classes de grosseur - Volume prélevés | U23: VMP | W23: VMA totale
C24: 20-40 | D24: 40-60 | E24: 60-70 | F24: 70-90 | G24: 90-120 | H24: 120-150 | I24: 150-180 | J24: 180+ | K24: VMV | L24: VMA | M24: 20-40 | N24: 40-60 | O24: 60-70 | P24: 70-90 | Q24: 90-120 | R24: 120-150 | S24: 150-180 | T24: 180+ | U24: VMP | V24: VMA
A25: années | B25: m | C25: m³/ha | D25: m³/ha | E25: m³/ha | F25: m³/ha | G25: m³/ha | H25: m³/ha | I25: m³/ha | J25: m³/ha | K25: € /ha | L25: € /ha | M25: m³/ha | N25: m³/ha | O25: m³/ha | P25: m³/ha | Q25: m³/ha | R25: m³/ha | S25: m³/ha | T25: m³/ha | U25: € /ha | V25: € /ha | W25: € /ha
A26: 23 | B26: 13.482303 | C26: 28.599269 | D26: 89.023883 | E26: 27.273138 | F26: 4.8287656 | G26: 0 | H26: 0 | I26: 0 | J26: 0 | K26: 2211.8763 | L26: 1402.6745 | M26: 10.098691 | N26: 26.163915 | O26: 7.37921 | P26: 1.2886391 | Q26: 0 | R26: 0 | S26: 0 | T26: 0 | U26: 578.81662 | V26: 367.05999 | W26: 1402.6745
A27: 29 | B27: 16.906645 | C27: 8.8414338 | D27: 74.39686 | E27: 51.317771 | F27: 69.209276 | G27: 2.1833219 | H27: 0 | I27: 0 | J27: 0 | K27: 5269.7425 | L27: 2967.4569 | M27: 4.6778108 | N27: 17.773796 | O27: 5.6953697 | P27: 7.1922222 | Q27: 0.19384735 | R27: 0 | S27: 0 | T27: 0 | U27: 643.7365 | V27: 362.49594 | W27: 3334.5168
A28: 35 | B28: 20.218879 | C28: 2.1677549 | D28: 37.746834 | E28: 48.344847 | F28: 119.17334 | G28: 72.757782 | H28: 0 | I28: 0 | J28: 0 | K28: 10424.21 | L28: 5212.393 | M28: 1.4689792 | N28: 15.207362 | O28: 9.3071432 | P28: 11.820482 | Q28: 6.3364033 | R28: 0 | S28: 0 | T28: 0 | U28: 1143.4912 | V28: 571.77716 | W28: 5941.9489
A29: 41 | B29: 23.356367 | C29: 0.32291348 | D29: 12.936371 | E29: 25.360956 | F29: 113.57773 | G29: 181.06721 | H29: 17.167978 | I29: 0 | J29: 0 | K29: 16079.149 | L29: 7139.3066 | M29: 0.26336222 | N29: 7.7647369 | O29: 10.106254 | P29: 20.296567 | Q29: 18.515606 | R29: 1.8730626 | S29: 0 | T29: 0 | U29: 2074.8807 | V29: 921.26821 | W29: 8440.6396
A30: 47 | B30: 26.295428 | C30: 0 | D30: 3.1376877 | E30: 7.9848194 | F30: 64.055729 | G30: 219.3738 | H30: 112.00313 | I30: 0 | J30: 0 | K30: 21735.828 | L30: 8569.7494 | M30: 0 | N30: 2.138254 | O30: 4.3783312 | P30: 23.234758 | Q30: 27.687448 | R30: 10.395863 | S30: 0 | T30: 0 | U30: 2934.3805 | V30: 1156.9334 | W30: 10792.351
A31: 53 | B31: 29.060241 | C31: 0 | D31: 0.42672825 | E31: 1.9182226 | F31: 20.384524 | G31: 183.87679 | H31: 212.27499 | I31: 33.277135 | J31: 0 | K31: 27074.021 | L31: 9478.5884 | M31: 0 | N31: 0.28501492 | O31: 1.5373715 | P31: 10.19263 | Q31: 33.516567 | R31: 20.58973 | S31: 2.0136498 | T31: 0 | U31: 3388.6109 | V31: 1186.3494 | W31: 12858.123
A32: 59 | B32: 31.660941 | C32: 0 | D32: 0 | E32: 0.24916644 | F32: 5.5613369 | G32: 98.802466 | H32: 246.47247 | I32: 144.38191 | J32: 0 | K32: 32782.591 | L32: 10191.383 | M32: 0 | N32: 0 | O32: 0.21376968 | P32: 3.8479476 | Q32: 29.61978 | R32: 23.44744 | S32: 10.558365 | T32: 0 | U32: 3701.9794 | V32: 1150.8636 | W32: 14757.267
A33: 65 | B33: 34.106295 | C33: 0 | D33: 0 | E33: 0 | F33: 0.47302017 | G33: 30.381598 | H33: 226.52247 | I33: 238.51998 | J33: 41.206759 | K33: 38436.348 | L33: 10610.38 | M33: 0 | N33: 0 | O33: 0 | P33: 0.47302017 | Q33: 14.045614 | R33: 32.370911 | S33: 17.404963 | T33: 3.2640698 | U33: 4098.4724 | V33: 1131.3861 | W33: 16327.128
A34: 71 | B34: 36.404045 | C34: 0 | D34: 0 | E34: 0 | F34: 0 | G34: 7.098576 | H34: 124.76801 | I34: 288.05943 | J34: 157.02738 | K34: 44172.749 | L34: 10827.85 | M34: 0 | N34: 0 | O34: 0 | P34: 0 | Q34: 4.7375497 | R34: 31.23632 | S34: 20.767702 | T34: 9.9363962 | U34: 4323.0227 | V34: 1059.6814 | W34: 17675.984
A35: 77 | B35: 38.591413 | C35: 0 | D35: 0 | E35: 0 | F35: 0 | G35: 0.68531917 | H35: 42.688038 | I35: 258.99268 | J35: 313.54336 | K35: 49525.227 | L35: 10779.863 | M35: 0 | N35: 0 | O35: 0 | P35: 0 | Q35: 0.54367773 | R35: 16.231791 | S35: 33.682581 | T35: 15.892992 | U35: 4589.2198 | V35: 998.90832 | W35: 18687.678
A36: 83 | B36: 40.676788 | C36: 0 | D36: 0 | E36: 0 | F36: 0 | G36: 0 | H36: 8.2376621 | I36: 162.01775 | J36: 483.11076 | K36: 54204.244 | L36: 10476.568 | M36: 0 | N36: 0 | O36: 0 | P36: 0 | Q36: 0 | R36: 5.8280171 | S36: 32.74594 | T36: 26.496143 | U36: 4695.3479 | V36: 907.51439 | W36: 19383.292
A37: 89 | B37: 42.661906 | C37: 0 | D37: 0 | E37: 0 | F37: 0 | G37: 0 | H37: 0.47302904 | I37: 51.54601 | J37: 639.05277 | K37: 58479.511 | L37: 10036.642 | M37: 0 | N37: 0 | O37: 0 | P37: 0 | Q37: 0 | R37: 0.47302904 | S37: 51.54601 | T37: 639.05277 | U37: 58479.511 | V37: 10036.642 | W37: 19850.88
A38: Total | B38: - | C38: - | D38: - | E38: - | F38: - | G38: - | H38: - | I38: - | J38: - | K38: - | L38: - | M38: 16.508843 | N38: 69.333078 | O38: 38.617449 | P38: 78.346266 | Q38: 135.19649 | R38: 142.44616 | S38: 168.71921 | T38: 694.64237 | U38: - | V38: 19850.88 | W38: -
W40: J. Perin, 2016
W41: (j.perin@ulg.ac.be)

Sheet Do0B
D1: Classe de productivité 0, plantation 2 x 2 m
A3: Caractéristiques : | E3: Essence : douglas | K3: Plantation : 2 x 2 (85% de reprise) | R3: Rotation : 6 ans
E4: Classe 0 (44 m à 50 ans) | K4: Cloisonnement : 1 ligne sur 11 | R4: Taux d'actualisation : 2 %
A5: Table de production
A6: Age | B6: Hdom | C6: Avant prélèvement | G6: Prélèvement | K6: Après prélèvement | O6: Accroissements | U6: h/d | V6: Ecl | W6: Dist
C7: Nha | D7: Cg | E7: Gha | F7: Vha | G7: Nha | H7: Cg | I7: Gha | J7: Vha | K7: Nha | L7: Cg | M7: Gha | N7: Vha | O7: ACC | P7: ACG | Q7: AMG | R7: ACV | S7: AMV | T7: PTV
A8: années | B8: m | C8: N/ha | D8: cm | E8: m²/ha | F8: m³/ha | G8: N/ha | H8: cm | I8: m²/ha | J8: m³/ha | K8: N/ha | L8: cm | M8: m²/ha | N8: m³/ha | O8: cm/ha/an | P8: m²/ha/an | Q8: m²/ha/an | R8: m³/ha/an | S8: m³/ha/an | T8: m³/ha | V8: % | W8: m
A9: 13 | B9: 13.159977 | C9: 2013.62 | D9: 42.22478 | E9: 28.569487 | F9: 150.63388 | G9: 800.42 | H9: 39.333541 | I9: 9.8544902 | J9: 49.844007 | K9: 1213.2 | L9: 44.028472 | M9: 18.714997 | N9: 100.78988 | O9: 2.8495281 | P9: 2.8397491 | Q9: 2.1976528 | R9: 29.150164 | S9: 11.587222 | T9: 150.63388 | U9: 93.901255 | V9: 39.7503 | W9: 3.0850946
A10: 19 | B10: 18.946624 | C10: 1202.49 | D10: 61.125641 | E10: 35.753491 | F10: 275.69086 | G10: 479.25 | H10: 53.326572 | I10: 10.845251 | J10: 80.317259 | K10: 723.24 | L10: 65.786266 | M10: 24.908241 | N10: 195.3736 | O10: 2.8937593 | P10: 2.4193891 | Q10: 2.4004201 | R10: 30.901538 | S10: 17.133414 | T10: 325.53487 | U10: 90.478726 | V10: 39.854801 | W10: 3.9957054
A11: 25 | B11: 24.453373 | C11: 716.58 | D11: 83.148822 | E11: 39.424575 | F11: 380.78283 | G11: 239.31 | H11: 72.083069 | I11: 9.8950393 | J11: 93.449603 | K11: 477.27 | L11: 88.176159 | M11: 29.529536 | N11: 287.33323 | O11: 2.9346246 | P11: 2.1083886 | Q11: 2.4049726 | R11: 31.361138 | S11: 20.437764 | T11: 510.94409 | U11: 87.123934 | V11: 33.396132 | W11: 4.9187258
A12: 31 | B12: 29.581287 | C12: 473.67 | D12: 105.78391 | E12: 42.179868 | F12: 475.50005 | G12: 138.78 | H12: 91.571372 | I12: 9.2605432 | J12: 103.05173 | K12: 334.89 | L12: 111.14228 | M12: 32.919325 | N12: 372.44832 | O12: 2.9885797 | P12: 1.8674558 | Q12: 2.3475693 | R12: 31.085341 | S12: 22.551965 | T12: 699.11092 | U12: 83.615664 | V12: 29.298879 | W12: 5.8719668
A13: 37 | B13: 34.291245 | C13: 332.82 | D13: 129.07376 | E13: 44.12406 | F13: 558.96037 | G13: 86.58 | H13: 114.23212 | I13: 8.9905067 | J13: 113.489 | K13: 246.24 | L13: 133.90188 | M13: 35.133553 | N13: 445.47137 | O13: 3.0343332 | P13: 1.6674224 | Q13: 2.2697131 | R13: 30.220752 | S13: 23.935756 | T13: 885.62297 | U13: 80.453781 | V13: 26.014062 | W13: 6.847868
A14: 43 | B14: 38.565694 | C14: 245.16 | D14: 152.10788 | E14: 45.138088 | F14: 626.79588 | G14: 55.35 | H14: 134.9541 | I14: 8.0219492 | J14: 111.36778 | K14: 189.81 | L14: 156.75694 | M14: 37.116138 | N14: 515.4281 | O14: 3.0673715 | P14: 1.5121874 | Q14: 2.1856725 | R14: 29.348352 | S14: 24.812732 | T14: 1066.9475 | U14: 77.290166 | V14: 22.577093 | W14: 7.7996504
